Workbook

Sheet TOTAL
E1: w1 | F1: =SUBTOTAL(9,E3:E10000) -> 2111.5 | K1: w2 | L1: =SUBTOTAL(9,K3:K10000) -> 2108.6 | Q1: w3 | R1: =SUBTOTAL(9,Q3:Q10000) -> 2494.9 | W1: w4 | X1: =SUBTOTAL(9,W3:W10000) -> 2015.6 | AC1: w5 | AD1: =SUBTOTAL(9,AC3:AC10000) -> 2310.9 | AI1: w6 | AJ1: =SUBTOTAL(9,AI3:AI10000) -> 1556.3 | AO1: w7 | AP1: =SUBTOTAL(9,AO3:AO10000) -> 1963.7 | AU1: w8 | AV1: =SUBTOTAL(9,AU3:AU10000) -> 2437.6 | BA1: w9 | BB1: =SUBTOTAL(9,BA3:BA10000) -> 2447 | BG1: w10 | BH1: =SUBTOTAL(9,BG3:BG10000) -> 2175.1 | BM1: w11 | BN1: =SUBTOTAL(9,BM3:BM10000) -> 2078 | BS1: w12 | BT1: =SUBTOTAL(9,BS3:BS10000) -> 1868.4 | BU1: 46097 | BV1: 46103 | BY1: w13 | BZ1: =SUBTOTAL(9,BY3:BY10000) -> 2080.8 | CA1: 46104 | CB1: 46110 | CE1: w14 | CF1: =SUBTOTAL(9,CE3:CE10000) -> 2164.3 | CG1: 46111 | CH1: 46117 | CM1: acc | CN1: 0.95 | CP1: 0.025 | CR1: 0.025 | CU1: St.Dev. | CV1: St.Dev. | CW1: St.Dev. | CX1: St.Dev. | CY1: St.Dev. | CZ1: St.Dev.
A2: Excl. | B2: Name STRAVA | C2: Name STRAVA 2 | D2: Aux1 | E2: Distance | F2: Pos. | G2: Avg. Pace | H2: Pos. | I2: Elev. Gain | J2: Pos. | K2: Distance | L2: Pos. | M2: Avg. Pace | N2: Pos. | O2: Elev. Gain | P2: Pos. | Q2: Distance | R2: Pos. | S2: Avg. Pace | T2: Pos. | U2: Elev. Gain | V2: Pos. | W2: Distance | X2: Pos. | Y2: Avg. Pace | Z2: Pos. | AA2: Elev. Gain | AB2: Pos. | AC2: Distance | AD2: Pos. | AE2: Avg. Pace | AF2: Pos. | AG2: Elev. Gain | AH2: Pos. | AI2: Distance | AJ2: Pos. | AK2: Avg. Pace | AL2: Pos. | AM2: Elev. Gain | AN2: Pos. | AO2: Distance | AP2: Pos. | AQ2: Avg. Pace | AR2: Pos. | AS2: Elev. Gain | AT2: Pos. | AU2: Distance | AV2: Pos. | AW2: Avg. Pace | AX2: Pos. | AY2: Elev. Gain | AZ2: Pos. | BA2: Distance | BB2: Pos. | BC2: Avg. Pace | BD2: Pos. | BE2: Elev. Gain | BF2: Pos. | BG2: Distance | BH2: Pos. | BI2: Avg. Pace | BJ2: Pos. | BK2: Elev. Gain | BL2: Pos. | BM2: Distance | BN2: Pos. | BO2: Avg. Pace | BP2: Pos. | BQ2: Elev. Gain | BR2: Pos. | BS2: Distance | BT2: Pos. | BU2: Avg. Pace | BV2: Pos. | BW2: Elev. Gain | BX2: Pos. | BY2: Distance | BZ2: Pos. | CA2: Avg. Pace | CB2: Pos. | CC2: Elev. Gain | CD2: Pos. | CE2: Distance | CF2: Pos. | CG2: Avg. Pace | CH2: Pos. | CI2: Elev. Gain | CJ2: Pos. | CK2: Pos. | CL2: Name | CM2: Distance | CN2: Pos. | CO2: Avg. Pace | CP2: Pos. | CQ2: Elev. Gain | CR2: Pos. | CS2: RANK | CT2: Aux2 | CU2: Distance | CV2: Pos. | CW2: Avg. Pace | CX2: Pos. | CY2: Elev. Gain | CZ2: Pos.
B3: Sérgio Miguel Sérgio Miguel | C3: Sérgio Miguel | D3: =CN3*$CN$1+CP3*$CP$1+CR3*$CR$1 -> 1.45 | E3: =IFERROR(_xlfn.XLOOKUP(B3,'w1'!$B:$B,'w1'!$C:$C),0) -> 113.3 | F3: =_xlfn.RANK.EQ(E3,E$3:E$10000,0) -> 1 | G3: =IFERROR(_xlfn.XLOOKUP(B3,'w1'!$B:$B,'w1'!$F:$F),1) -> 0.22986111 | H3: =_xlfn.RANK.EQ(G3,G$3:G$10000,1) -> 10 | I3: =IFERROR(IF(_xlfn.XLOOKUP(B3,'w1'!$B:$B,'w1'!$G:$G)="--",0,_xlfn.XLOOKUP(B3,'w1'!$B:$B,'w1'!$G:$G)),0) -> 1338 | J3: =_xlfn.RANK.EQ(I3,I$3:I$10000,0) -> 4 | K3: =IFERROR(_xlfn.XLOOKUP(B3,'w2'!$B:$B,'w2'!$C:$C),0) -> 107.7 | L3: =_xlfn.RANK.EQ(K3,K$3:K$10000,0) -> 1 | M3: =IFERROR(_xlfn.XLOOKUP(B3,'w2'!$B:$B,'w2'!$F:$F),1) -> 0.29027778 | N3: =_xlfn.RANK.EQ(M3,M$3:M$10000,1) -> 44 | O3: =IFERROR(IF(_xlfn.XLOOKUP(B3,'w2'!$B:$B,'w2'!$G:$G)="--",0,_xlfn.XLOOKUP(B3,'w2'!$B:$B,'w2'!$G:$G)),0) -> 3385 | P3: =_xlfn.RANK.EQ(O3,O$3:O$10000,0) -> 1 | Q3: =IFERROR(_xlfn.XLOOKUP(B3,'w3'!$B:$B,'w3'!$C:$C),0) -> 69.8 | R3: =_xlfn.RANK.EQ(Q3,Q$3:Q$10000,0) -> 5 | S3: =IFERROR(_xlfn.XLOOKUP(B3,'w3'!$B:$B,'w3'!$F:$F),1) -> 0.29861111 | T3: =_xlfn.RANK.EQ(S3,S$3:S$10000,1) -> 50 | U3: =IFERROR(IF(_xlfn.XLOOKUP(B3,'w3'!$B:$B,'w3'!$G:$G)="--",0,_xlfn.XLOOKUP(B3,'w3'!$B:$B,'w3'!$G:$G)),0) -> 2336 | V3: =_xlfn.RANK.EQ(U3,U$3:U$10000,0) -> 4 | W3: =IFERROR(_xlfn.XLOOKUP(B3,'w4'!$B:$B,'w4'!$C:$C),0) -> 125 | X3: =_xlfn.RANK.EQ(W3,W$3:W$10000,0) -> 1 | Y3: =IFERROR(_xlfn.XLOOKUP(B3,'w4'!$B:$B,'w4'!$F:$F),1) -> 0.23680556 | Z3: =_xlfn.RANK.EQ(Y3,Y$3:Y$10000,1) -> 10 | AA3: =IFERROR(IF(_xlfn.XLOOKUP(B3,'w4'!$B:$B,'w4'!$G:$G)="--",0,_xlfn.XLOOKUP(B3,'w4'!$B:$B,'w4'!$G:$G)),0) -> 1174 | AB3: =_xlfn.RANK.EQ(AA3,AA$3:AA$10000,0) -> 10 | AC3: =IFERROR(_xlfn.XLOOKUP(B3,'w5'!$B:$B,'w5'!$C:$C),0) -> 106 | AD3: =_xlfn.RANK.EQ(AC3,AC$3:AC$10000,0) -> 1 | AE3: =IFERROR(_xlfn.XLOOKUP(B3,'w5'!$B:$B,'w5'!$F:$F),1) -> 0.26319444 | AF3: =_xlfn.RANK.EQ(AE3,AE$3:AE$10000,1) -> 27 | AG3: =IFERROR(IF(_xlfn.XLOOKUP(B3,'w5'!$B:$B,'w5'!$G:$G)="--",0,_xlfn.XLOOKUP(B3,'w5'!$B:$B,'w5'!$G:$G)),0) -> 2159 | AH3: =_xlfn.RANK.EQ(AG3,AG$3:AG$10000,0) -> 2 | AI3: =IFERROR(_xlfn.XLOOKUP(B3,'w6'!$B:$B,'w6'!$C:$C),0) -> 120.8 | AJ3: =_xlfn.RANK.EQ(AI3,AI$3:AI$10000,0) -> 1 | AK3: =IFERROR(_xlfn.XLOOKUP(B3,'w6'!$B:$B,'w6'!$F:$F),1) -> 0.22569444 | AL3: =_xlfn.RANK.EQ(AK3,AK$3:AK$10000,1) -> 4 | AM3: =IFERROR(IF(_xlfn.XLOOKUP(B3,'w6'!$B:$B,'w6'!$G:$G)="--",0,_xlfn.XLOOKUP(B3,'w6'!$B:$B,'w6'!$G:$G)),0) -> 950 | AN3: =_xlfn.RANK.EQ(AM3,AM$3:AM$10000,0) -> 6 | AO3: =IFERROR(_xlfn.XLOOKUP(B3,'w7'!$B:$B,'w7'!$C:$C),0) -> 127.3 | AP3: =_xlfn.RANK.EQ(AO3,AO$3:AO$10000,0) -> 1 | AQ3: =IFERROR(_xlfn.XLOOKUP(B3,'w7'!$B:$B,'w7'!$F:$F),1) -> 0.25 | AR3: =_xlfn.RANK.EQ(AQ3,AQ$3:AQ$10000,1) -> 19 | AS3: =IFERROR(IF(_xlfn.XLOOKUP(B3,'w7'!$B:$B,'w7'!$G:$G)="--",0,_xlfn.XLOOKUP(B3,'w7'!$B:$B,'w7'!$G:$G)),0) -> 2374 | AT3: =_xlfn.RANK.EQ(AS3,AS$3:AS$10000,0) -> 1 | AU3: =IFERROR(_xlfn.XLOOKUP(B3,'w8'!$B:$B,'w8'!$C:$C),0) -> 136.5 | AV3: =_xlfn.RANK.EQ(AU3,AU$3:AU$10000,0) -> 1 | AW3: =IFERROR(_xlfn.XLOOKUP(B3,'w8'!$B:$B,'w8'!$F:$F),1) -> 0.24513889 | AX3: =_xlfn.RANK.EQ(AW3,AW$3:AW$10000,1) -> 12 | AY3: =IFERROR(IF(_xlfn.XLOOKUP(B3,'w8'!$B:$B,'w8'!$G:$G)="--",0,_xlfn.XLOOKUP(B3,'w8'!$B:$B,'w8'!$G:$G)),0) -> 2097 | AZ3: =_xlfn.RANK.EQ(AY3,AY$3:AY$10000,0) -> 4 | BA3: =IFERROR(_xlfn.XLOOKUP(C3,'w9'!$B:$B,'w9'!$C:$C),0) -> 33.1 | BB3: =_xlfn.RANK.EQ(BA3,BA$3:BA$10000,0) -> 33 | BC3: =IFERROR(_xlfn.XLOOKUP(C3,'w9'!$B:$B,'w9'!$F:$F),1) -> 0.22638889 | BD3: =_xlfn.RANK.EQ(BC3,BC$3:BC$10000,1) -> 5 | BE3: =IFERROR(IF(_xlfn.XLOOKUP(C3,'w9'!$B:$B,'w9'!$G:$G)="--",0,_xlfn.XLOOKUP(C3,'w9'!$B:$B,'w9'!$G:$G)),0) -> 494 | BF3: =_xlfn.RANK.EQ(BE3,BE$3:BE$10000,0) -> 27 | BG3: =IFERROR(_xlfn.XLOOKUP(B3,'w10'!$B:$B,'w10'!$C:$C),0) -> 108 | BH3: =_xlfn.RANK.EQ(BG3,BG$3:BG$10000,0) -> 1 | BI3: =IFERROR(_xlfn.XLOOKUP(B3,'w10'!$B:$B,'w10'!$F:$F),1) -> 0.24583333 | BJ3: =_xlfn.RANK.EQ(BI3,BI$3:BI$10000,1) -> 19 | BK3: =IFERROR(IF(_xlfn.XLOOKUP(B3,'w10'!$B:$B,'w10'!$G:$G)="--",0,_xlfn.XLOOKUP(B3,'w10'!$B:$B,'w10'!$G:$G)),0) -> 1838 | BL3: =_xlfn.RANK.EQ(BK3,BK$3:BK$10000,0) -> 5 | BM3: =IFERROR(_xlfn.XLOOKUP(B3,'w11'!$B:$B,'w11'!$C:$C),0) -> 109.2 | BN3: =_xlfn.RANK.EQ(BM3,BM$3:BM$10000,0) -> 1 | BO3: =IFERROR(_xlfn.XLOOKUP(B3,'w11'!$B:$B,'w11'!$F:$F),1) -> 0.24513889 | BP3: =_xlfn.RANK.EQ(BO3,BO$3:BO$10000,1) -> 17 | BQ3: =IFERROR(IF(_xlfn.XLOOKUP(B3,'w11'!$B:$B,'w11'!$G:$G)="--",0,_xlfn.XLOOKUP(B3,'w11'!$B:$B,'w11'!$G:$G)),0) -> 2611 | BR3: =_xlfn.RANK.EQ(BQ3,BQ$3:BQ$10000,0) -> 1 | BS3: =IFERROR(_xlfn.XLOOKUP(B3,'w12'!$B:$B,'w12'!$C:$C),0) -> 125.9 | BT3: =_xlfn.RANK.EQ(BS3,BS$3:BS$10000,0) -> 1 | BU3: =IFERROR(_xlfn.XLOOKUP(B3,'w12'!$B:$B,'w12'!$F:$F),1) -> 0.24305556 | BV3: =_xlfn.RANK.EQ(BU3,BU$3:BU$10000,1) -> 15 | BW3: =IFERROR(IF(_xlfn.XLOOKUP(B3,'w12'!$B:$B,'w12'!$G:$G)="--",0,_xlfn.XLOOKUP(B3,'w12'!$B:$B,'w12'!$G:$G)),0) -> 1959 | BX3: =_xlfn.RANK.EQ(BW3,BW$3:BW$10000,0) -> 3 | BY3: =IFERROR(_xlfn.XLOOKUP(B3,'w13'!$B:$B,'w13'!$C:$C),0) -> 138.3 | BZ3: =_xlfn.RANK.EQ(BY3,BY$3:BY$10000,0) -> 1 | CA3: =IFERROR(_xlfn.XLOOKUP(B3,'w13'!$B:$B,'w13'!$F:$F),1) -> 0.25 | CB3: =_xlfn.RANK.EQ(CA3,CA$3:CA$10000,1) -> 23 | CC3: =IFERROR(IF(_xlfn.XLOOKUP(B3,'w13'!$B:$B,'w13'!$G:$G)="--",0,_xlfn.XLOOKUP(B3,'w13'!$B:$B,'w13'!$G:$G)),0) -> 2800 | CD3: =_xlfn.RANK.EQ(CC3,CC$3:CC$10000,0) -> 1 | CE3: =IFERROR(_xlfn.XLOOKUP(B3,'w14'!$B:$B,'w14'!$C:$C),0) -> 117.3 | CF3: =_xlfn.RANK.EQ(CE3,CE$3:CE$10000,0) -> 1 | CG3: =IFERROR(_xlfn.XLOOKUP(B3,'w14'!$B:$B,'w14'!$F:$F),1) -> 0.26527778 | CH3: =_xlfn.RANK.EQ(CG3,CG$3:CG$10000,1) -> 25 | CI3: =IFERROR(IF(_xlfn.XLOOKUP(B3,'w14'!$B:$B,'w14'!$G:$G)="--",0,_xlfn.XLOOKUP(B3,'w14'!$B:$B,'w14'!$G:$G)),0) -> 2735 | CJ3: =_xlfn.RANK.EQ(CI3,CI$3:CI$10000,0) -> 1 | CK3: =_xlfn.RANK.EQ(D3,D$3:D$10000,1) -> 1 | CL3: Sérgio Miguel | CM3: =SUM(E3,K3,Q3,W3,AC3,AI3,AO3,AU3,BA3,BG3,BM3,BS3,BY3,CE3) -> 1538.2 | CN3: =_xlfn.RANK.EQ(CM3,CM$3:CM$10000) -> 1 | CO3: =IFERROR(SUM(PRODUCT(E3,G3),PRODUCT(K3,M3),PRODUCT(Q3,S3),PRODUCT(W3,Y3),PRODUCT(AC3,AE3),PRODUCT(AI3,AK3),PRODUCT(AO3,AQ3),PRODUCT(AU3,AW3),PRODUCT(BA3,BC3),PRODUCT(BG3,BI3),PRODUCT(BM3,BO3),PRODUCT(BS3,BU3),PRODUCT(BY3,CA3),PRODUCT(CE3,CG3))/CM3,1) -> 0.25049038 | CP3: =_xlfn.RANK.EQ(CO3,CO$3:CO$10000,1) -> 19 | CQ3: =SUM(I3,O3,U3,AA3,AG3,AM3,AS3,AY3,BE3,BK3,BQ3,BW3,CC3,CI3) -> 28250 | CR3: =_xlfn.RANK.EQ(CQ3,CQ$3:CQ$10000) -> 1 | CS3: =_xlfn.RANK.EQ(CT3,CT$3:CT$10000,1) -> 6 | CT3: =CV3*$CN$1+CX3*$CP$1+CZ3*$CR$1 -> 28.05 | CU3: =_xlfn.STDEV.S(F3,L3,R3,X3,AD3,AJ3,AP3,AV3,BB3,BH3,BN3,BT3,BZ3,CF3) -> 8.5369269 | CV3: =_xlfn.RANK.EQ(CU3,CU$3:CU$10000,1) -> 28 | CW3: =_xlfn.STDEV.S(H3,N3,T3,Z3,AF3,AL3,AR3,AX3,BD3,BJ3,BP3,BV3,CB3,CH3) -> 13.416408 | CX3: =_xlfn.RANK.EQ(CW3,CW$3:CW$10000,1) -> 46 | CY3: =_xlfn.STDEV.S(J3,P3,V3,AB3,AH3,AN3,AT3,AZ3,BF3,BL3,BR3,BX3,CD3,CJ3) -> 6.827546 | CZ3: =_xlfn.RANK.EQ(CY3,CY$3:CY$10000,1) -> 12 | DA3: =SUM(COUNTIF(E3,">0"),COUNTIF(K3,">0"),COUNTIF(Q3,">0"),COUNTIF(W3,">0"),COUNTIF(AC3,">0"),COUNTIF(AI3,">0"),COUNTIF(AO3,">0"),COUNTIF(AU3,">0"),COUNTIF(BA3,">0"),COUNTIF(BG3,">0"),COUNTIF(BM3,">0"),COUNTIF(BS3,">0"),COUNTIF(BY3,">0"),COUNTIF(CE3,">0")) -> 14
B4: Sara Pedrosa Sara Pedrosa | C4: Sara Pedrosa | D4: =CN4*$CN$1+CP4*$CP$1+CR4*$CR$1 -> 2.3 | E4: =IFERROR(_xlfn.XLOOKUP(B4,'w1'!$B:$B,'w1'!$C:$C),0) -> 53.2 | F4: =_xlfn.RANK.EQ(E4,E$3:E$10000,0) -> 10 | G4: =IFERROR(_xlfn.XLOOKUP(B4,'w1'!$B:$B,'w1'!$F:$F),1) -> 0.21041667 | H4: =_xlfn.RANK.EQ(G4,G$3:G$10000,1) -> 4 | I4: =IFERROR(IF(_xlfn.XLOOKUP(B4,'w1'!$B:$B,'w1'!$G:$G)="--",0,_xlfn.XLOOKUP(B4,'w1'!$B:$B,'w1'!$G:$G)),0) -> 208 | J4: =_xlfn.RANK.EQ(I4,I$3:I$10000,0) -> 45 | K4: =IFERROR(_xlfn.XLOOKUP(B4,'w2'!$B:$B,'w2'!$C:$C),0) -> 84.4 | L4: =_xlfn.RANK.EQ(K4,K$3:K$10000,0) -> 3 | M4: =IFERROR(_xlfn.XLOOKUP(B4,'w2'!$B:$B,'w2'!$F:$F),1) -> 0.20833333 | N4: =_xlfn.RANK.EQ(M4,M$3:M$10000,1) -> 2 | O4: =IFERROR(IF(_xlfn.XLOOKUP(B4,'w2'!$B:$B,'w2'!$G:$G)="--",0,_xlfn.XLOOKUP(B4,'w2'!$B:$B,'w2'!$G:$G)),0) -> 329 | P4: =_xlfn.RANK.EQ(O4,O$3:O$10000,0) -> 30 | Q4: =IFERROR(_xlfn.XLOOKUP(B4,'w3'!$B:$B,'w3'!$C:$C),0) -> 82 | R4: =_xlfn.RANK.EQ(Q4,Q$3:Q$10000,0) -> 3 | S4: =IFERROR(_xlfn.XLOOKUP(B4,'w3'!$B:$B,'w3'!$F:$F),1) -> 0.23263889 | T4: =_xlfn.RANK.EQ(S4,S$3:S$10000,1) -> 6 | U4: =IFERROR(IF(_xlfn.XLOOKUP(B4,'w3'!$B:$B,'w3'!$G:$G)="--",0,_xlfn.XLOOKUP(B4,'w3'!$B:$B,'w3'!$G:$G)),0) -> 891 | V4: =_xlfn.RANK.EQ(U4,U$3:U$10000,0) -> 13 | W4: =IFERROR(_xlfn.XLOOKUP(B4,'w4'!$B:$B,'w4'!$C:$C),0) -> 84.3 | X4: =_xlfn.RANK.EQ(W4,W$3:W$10000,0) -> 2 | Y4: =IFERROR(_xlfn.XLOOKUP(B4,'w4'!$B:$B,'w4'!$F:$F),1) -> 0.26041667 | Z4: =_xlfn.RANK.EQ(Y4,Y$3:Y$10000,1) -> 30 | AA4: =IFERROR(IF(_xlfn.XLOOKUP(B4,'w4'!$B:$B,'w4'!$G:$G)="--",0,_xlfn.XLOOKUP(B4,'w4'!$B:$B,'w4'!$G:$G)),0) -> 2139 | AB4: =_xlfn.RANK.EQ(AA4,AA$3:AA$10000,0) -> 2 | AC4: =IFERROR(_xlfn.XLOOKUP(B4,'w5'!$B:$B,'w5'!$C:$C),0) -> 81.3 | AD4: =_xlfn.RANK.EQ(AC4,AC$3:AC$10000,0) -> 2 | AE4: =IFERROR(_xlfn.XLOOKUP(B4,'w5'!$B:$B,'w5'!$F:$F),1) -> 0.23819444 | AF4: =_xlfn.RANK.EQ(AE4,AE$3:AE$10000,1) -> 14 | AG4: =IFERROR(IF(_xlfn.XLOOKUP(B4,'w5'!$B:$B,'w5'!$G:$G)="--",0,_xlfn.XLOOKUP(B4,'w5'!$B:$B,'w5'!$G:$G)),0) -> 1743 | AH4: =_xlfn.RANK.EQ(AG4,AG$3:AG$10000,0) -> 6 | AI4: =IFERROR(_xlfn.XLOOKUP(B4,'w6'!$B:$B,'w6'!$C:$C),0) -> 87.2 | AJ4: =_xlfn.RANK.EQ(AI4,AI$3:AI$10000,0) -> 2 | AK4: =IFERROR(_xlfn.XLOOKUP(B4,'w6'!$B:$B,'w6'!$F:$F),1) -> 0.2375 | AL4: =_xlfn.RANK.EQ(AK4,AK$3:AK$10000,1) -> 7 | AM4: =IFERROR(IF(_xlfn.XLOOKUP(B4,'w6'!$B:$B,'w6'!$G:$G)="--",0,_xlfn.XLOOKUP(B4,'w6'!$B:$B,'w6'!$G:$G)),0) -> 1737 | AN4: =_xlfn.RANK.EQ(AM4,AM$3:AM$10000,0) -> 1 | AO4: =IFERROR(_xlfn.XLOOKUP(B4,'w7'!$B:$B,'w7'!$C:$C),0) -> 61.4 | AP4: =_xlfn.RANK.EQ(AO4,AO$3:AO$10000,0) -> 5 | AQ4: =IFERROR(_xlfn.XLOOKUP(B4,'w7'!$B:$B,'w7'!$F:$F),1) -> 0.24166667 | AR4: =_xlfn.RANK.EQ(AQ4,AQ$3:AQ$10000,1) -> 13 | AS4: =IFERROR(IF(_xlfn.XLOOKUP(B4,'w7'!$B:$B,'w7'!$G:$G)="--",0,_xlfn.XLOOKUP(B4,'w7'!$B:$B,'w7'!$G:$G)),0) -> 1208 | AT4: =_xlfn.RANK.EQ(AS4,AS$3:AS$10000,0) -> 12 | AU4: =IFERROR(_xlfn.XLOOKUP(B4,'w8'!$B:$B,'w8'!$C:$C),0) -> 76.3 | AV4: =_xlfn.RANK.EQ(AU4,AU$3:AU$10000,0) -> 6 | AW4: =IFERROR(_xlfn.XLOOKUP(B4,'w8'!$B:$B,'w8'!$F:$F),1) -> 0.23402778 | AX4: =_xlfn.RANK.EQ(AW4,AW$3:AW$10000,1) -> 8 | AY4: =IFERROR(IF(_xlfn.XLOOKUP(B4,'w8'!$B:$B,'w8'!$G:$G)="--",0,_xlfn.XLOOKUP(B4,'w8'!$B:$B,'w8'!$G:$G)),0) -> 1503 | AZ4: =_xlfn.RANK.EQ(AY4,AY$3:AY$10000,0) -> 6 | BA4: =IFERROR(_xlfn.XLOOKUP(C4,'w9'!$B:$B,'w9'!$C:$C),0) -> 90.2 | BB4: =_xlfn.RANK.EQ(BA4,BA$3:BA$10000,0) -> 1 | BC4: =IFERROR(_xlfn.XLOOKUP(C4,'w9'!$B:$B,'w9'!$F:$F),1) -> 0.24583333 | BD4: =_xlfn.RANK.EQ(BC4,BC$3:BC$10000,1) -> 13 | BE4: =IFERROR(IF(_xlfn.XLOOKUP(C4,'w9'!$B:$B,'w9'!$G:$G)="--",0,_xlfn.XLOOKUP(C4,'w9'!$B:$B,'w9'!$G:$G)),0) -> 2093 | BF4: =_xlfn.RANK.EQ(BE4,BE$3:BE$10000,0) -> 2 | BG4: =IFERROR(_xlfn.XLOOKUP(B4,'w10'!$B:$B,'w10'!$C:$C),0) -> 98.2 | BH4: =_xlfn.RANK.EQ(BG4,BG$3:BG$10000,0) -> 2 | BI4: =IFERROR(_xlfn.XLOOKUP(B4,'w10'!$B:$B,'w10'!$F:$F),1) -> 0.25069444 | BJ4: =_xlfn.RANK.EQ(BI4,BI$3:BI$10000,1) -> 21 | BK4: =IFERROR(IF(_xlfn.XLOOKUP(B4,'w10'!$B:$B,'w10'!$G:$G)="--",0,_xlfn.XLOOKUP(B4,'w10'!$B:$B,'w10'!$G:$G)),0) -> 2515 | BL4: =_xlfn.RANK.EQ(BK4,BK$3:BK$10000,0) -> 2 | BM4: =IFERROR(_xlfn.XLOOKUP(B4,'w11'!$B:$B,'w11'!$C:$C),0) -> 79.3 | BN4: =_xlfn.RANK.EQ(BM4,BM$3:BM$10000,0) -> 2 | BO4: =IFERROR(_xlfn.XLOOKUP(B4,'w11'!$B:$B,'w11'!$F:$F),1) -> 0.22777778 | BP4: =_xlfn.RANK.EQ(BO4,BO$3:BO$10000,1) -> 10 | BQ4: =IFERROR(IF(_xlfn.XLOOKUP(B4,'w11'!$B:$B,'w11'!$G:$G)="--",0,_xlfn.XLOOKUP(B4,'w11'!$B:$B,'w11'!$G:$G)),0) -> 1622 | BR4: =_xlfn.RANK.EQ(BQ4,BQ$3:BQ$10000,0) -> 5 | BS4: =IFERROR(_xlfn.XLOOKUP(B4,'w12'!$B:$B,'w12'!$C:$C),0) -> 97 | BT4: =_xlfn.RANK.EQ(BS4,BS$3:BS$10000,0) -> 2 | BU4: =IFERROR(_xlfn.XLOOKUP(B4,'w12'!$B:$B,'w12'!$F:$F),1) -> 0.27291667 | BV4: =_xlfn.RANK.EQ(BU4,BU$3:BU$10000,1) -> 37 | BW4: =IFERROR(IF(_xlfn.XLOOKUP(B4,'w12'!$B:$B,'w12'!$G:$G)="--",0,_xlfn.XLOOKUP(B4,'w12'!$B:$B,'w12'!$G:$G)),0) -> 2734 | BX4: =_xlfn.RANK.EQ(BW4,BW$3:BW$10000,0) -> 1 | BY4: =IFERROR(_xlfn.XLOOKUP(B4,'w13'!$B:$B,'w13'!$C:$C),0) -> 80.3 | BZ4: =_xlfn.RANK.EQ(BY4,BY$3:BY$10000,0) -> 3 | CA4: =IFERROR(_xlfn.XLOOKUP(B4,'w13'!$B:$B,'w13'!$F:$F),1) -> 0.26388889 | CB4: =_xlfn.RANK.EQ(CA4,CA$3:CA$10000,1) -> 30 | CC4: =IFERROR(IF(_xlfn.XLOOKUP(B4,'w13'!$B:$B,'w13'!$G:$G)="--",0,_xlfn.XLOOKUP(B4,'w13'!$B:$B,'w13'!$G:$G)),0) -> 2118 | CD4: =_xlfn.RANK.EQ(CC4,CC$3:CC$10000,0) -> 3 | CE4: =IFERROR(_xlfn.XLOOKUP(B4,'w14'!$B:$B,'w14'!$C:$C),0) -> 72.9 | CF4: =_xlfn.RANK.EQ(CE4,CE$3:CE$10000,0) -> 3 | CG4: =IFERROR(_xlfn.XLOOKUP(B4,'w14'!$B:$B,'w14'!$F:$F),1) -> 0.25486111 | CH4: =_xlfn.RANK.EQ(CG4,CG$3:CG$10000,1) -> 16 | CI4: =IFERROR(IF(_xlfn.XLOOKUP(B4,'w14'!$B:$B,'w14'!$G:$G)="--",0,_xlfn.XLOOKUP(B4,'w14'!$B:$B,'w14'!$G:$G)),0) -> 2063 | CJ4: =_xlfn.RANK.EQ(CI4,CI$3:CI$10000,0) -> 5 | CK4: =_xlfn.RANK.EQ(D4,D$3:D$10000,1) -> 2 | CL4: Sara Pedrosa | CM4: =SUM(E4,K4,Q4,W4,AC4,AI4,AO4,AU4,BA4,BG4,BM4,BS4,BY4,CE4) -> 1128 | CN4: =_xlfn.RANK.EQ(CM4,CM$3:CM$10000) -> 2 | CO4: =IFERROR(SUM(PRODUCT(E4,G4),PRODUCT(K4,M4),PRODUCT(Q4,S4),PRODUCT(W4,Y4),PRODUCT(AC4,AE4),PRODUCT(AI4,AK4),PRODUCT(AO4,AQ4),PRODUCT(AU4,AW4),PRODUCT(BA4,BC4),PRODUCT(BG4,BI4),PRODUCT(BM4,BO4),PRODUCT(BS4,BU4),PRODUCT(BY4,CA4),PRODUCT(CE4,CG4))/CM4,1) -> 0.24261931 | CP4: =_xlfn.RANK.EQ(CO4,CO$3:CO$10000,1) -> 12 | CQ4: =SUM(I4,O4,U4,AA4,AG4,AM4,AS4,AY4,BE4,BK4,BQ4,BW4,CC4,CI4) -> 22903 | CR4: =_xlfn.RANK.EQ(CQ4,CQ$3:CQ$10000) -> 4 | CS4: =_xlfn.RANK.EQ(CT4,CT$3:CT$10000,1) -> 1 | CT4: =CV4*$CN$1+CX4*$CP$1+CZ4*$CR$1 -> 2.775 | CU4: =_xlfn.STDEV.S(F4,L4,R4,X4,AD4,AJ4,AP4,AV4,BB4,BH4,BN4,BT4,BZ4,CF4) -> 2.3346412 | CV4: =_xlfn.RANK.EQ(CU4,CU$3:CU$10000,1) -> 1 | CW4: =_xlfn.STDEV.S(H4,N4,T4,Z4,AF4,AL4,AR4,AX4,BD4,BJ4,BP4,BV4,CB4,CH4) -> 10.702008 | CX4: =_xlfn.RANK.EQ(CW4,CW$3:CW$10000,1) -> 31 | CY4: =_xlfn.STDEV.S(J4,P4,V4,AB4,AH4,AN4,AT4,AZ4,BF4,BL4,BR4,BX4,CD4,CJ4) -> 12.768652 | CZ4: =_xlfn.RANK.EQ(CY4,CY$3:CY$10000,1) -> 42 | DA4: =SUM(COUNTIF(E4,">0"),COUNTIF(K4,">0"),COUNTIF(Q4,">0"),COUNTIF(W4,">0"),COUNTIF(AC4,">0"),COUNTIF(AI4,">0"),COUNTIF(AO4,">0"),COUNTIF(AU4,">0"),COUNTIF(BA4,">0"),COUNTIF(BG4,">0"),COUNTIF(BM4,">0"),COUNTIF(BS4,">0"),COUNTIF(BY4,">0"),COUNTIF(CE4,">0")) -> 14
B5: Carlos Vaz Vignolo Carlos Vaz Vignolo | C5: Carlos Vaz Vignolo | D5: =CN5*$CN$1+CP5*$CP$1+CR5*$CR$1 -> 3.875 | E5: =IFERROR(_xlfn.XLOOKUP(B5,'w1'!$B:$B,'w1'!$C:$C),0) -> 59.2 | F5: =_xlfn.RANK.EQ(E5,E$3:E$10000,0) -> 6 | G5: =IFERROR(_xlfn.XLOOKUP(B5,'w1'!$B:$B,'w1'!$F:$F),1) -> 0.25416667 | H5: =_xlfn.RANK.EQ(G5,G$3:G$10000,1) -> 23 | I5: =IFERROR(IF(_xlfn.XLOOKUP(B5,'w1'!$B:$B,'w1'!$G:$G)="--",0,_xlfn.XLOOKUP(B5,'w1'!$B:$B,'w1'!$G:$G)),0) -> 381 | J5: =_xlfn.RANK.EQ(I5,I$3:I$10000,0) -> 24 | K5: =IFERROR(_xlfn.XLOOKUP(B5,'w2'!$B:$B,'w2'!$C:$C),0) -> 77.5 | L5: =_xlfn.RANK.EQ(K5,K$3:K$10000,0) -> 5 | M5: =IFERROR(_xlfn.XLOOKUP(B5,'w2'!$B:$B,'w2'!$F:$F),1) -> 0.25902778 | N5: =_xlfn.RANK.EQ(M5,M$3:M$10000,1) -> 21 | O5: =IFERROR(IF(_xlfn.XLOOKUP(B5,'w2'!$B:$B,'w2'!$G:$G)="--",0,_xlfn.XLOOKUP(B5,'w2'!$B:$B,'w2'!$G:$G)),0) -> 705 | P5: =_xlfn.RANK.EQ(O5,O$3:O$10000,0) -> 11 | Q5: =IFERROR(_xlfn.XLOOKUP(B5,'w3'!$B:$B,'w3'!$C:$C),0) -> 75 | R5: =_xlfn.RANK.EQ(Q5,Q$3:Q$10000,0) -> 4 | S5: =IFERROR(_xlfn.XLOOKUP(B5,'w3'!$B:$B,'w3'!$F:$F),1) -> 0.26388889 | T5: =_xlfn.RANK.EQ(S5,S$3:S$10000,1) -> 33 | U5: =IFERROR(IF(_xlfn.XLOOKUP(B5,'w3'!$B:$B,'w3'!$G:$G)="--",0,_xlfn.XLOOKUP(B5,'w3'!$B:$B,'w3'!$G:$G)),0) -> 1216 | V5: =_xlfn.RANK.EQ(U5,U$3:U$10000,0) -> 9 | W5: =IFERROR(_xlfn.XLOOKUP(B5,'w4'!$B:$B,'w4'!$C:$C),0) -> 77 | X5: =_xlfn.RANK.EQ(W5,W$3:W$10000,0) -> 3 | Y5: =IFERROR(_xlfn.XLOOKUP(B5,'w4'!$B:$B,'w4'!$F:$F),1) -> 0.25486111 | Z5: =_xlfn.RANK.EQ(Y5,Y$3:Y$10000,1) -> 27 | AA5: =IFERROR(IF(_xlfn.XLOOKUP(B5,'w4'!$B:$B,'w4'!$G:$G)="--",0,_xlfn.XLOOKUP(B5,'w4'!$B:$B,'w4'!$G:$G)),0) -> 654 | AB5: =_xlfn.RANK.EQ(AA5,AA$3:AA$10000,0) -> 13 | AC5: =IFERROR(_xlfn.XLOOKUP(B5,'w5'!$B:$B,'w5'!$C:$C),0) -> 44.8 | AD5: =_xlfn.RANK.EQ(AC5,AC$3:AC$10000,0) -> 15 | AE5: =IFERROR(_xlfn.XLOOKUP(B5,'w5'!$B:$B,'w5'!$F:$F),1) -> 0.26388889 | AF5: =_xlfn.RANK.EQ(AE5,AE$3:AE$10000,1) -> 28 | AG5: =IFERROR(IF(_xlfn.XLOOKUP(B5,'w5'!$B:$B,'w5'!$G:$G)="--",0,_xlfn.XLOOKUP(B5,'w5'!$B:$B,'w5'!$G:$G)),0) -> 518 | AH5: =_xlfn.RANK.EQ(AG5,AG$3:AG$10000,0) -> 27 | AI5: =IFERROR(_xlfn.XLOOKUP(B5,'w6'!$B:$B,'w6'!$C:$C),0) -> 70.2 | AJ5: =_xlfn.RANK.EQ(AI5,AI$3:AI$10000,0) -> 3 | AK5: =IFERROR(_xlfn.XLOOKUP(B5,'w6'!$B:$B,'w6'!$F:$F),1) -> 0.25972222 | AL5: =_xlfn.RANK.EQ(AK5,AK$3:AK$10000,1) -> 21 | AM5: =IFERROR(IF(_xlfn.XLOOKUP(B5,'w6'!$B:$B,'w6'!$G:$G)="--",0,_xlfn.XLOOKUP(B5,'w6'!$B:$B,'w6'!$G:$G)),0) -> 816 | AN5: =_xlfn.RANK.EQ(AM5,AM$3:AM$10000,0) -> 9 | AO5: =IFERROR(_xlfn.XLOOKUP(B5,'w7'!$B:$B,'w7'!$C:$C),0) -> 70.4 | AP5: =_xlfn.RANK.EQ(AO5,AO$3:AO$10000,0) -> 2 | AQ5: =IFERROR(_xlfn.XLOOKUP(B5,'w7'!$B:$B,'w7'!$F:$F),1) -> 0.22638889 | AR5: =_xlfn.RANK.EQ(AQ5,AQ$3:AQ$10000,1) -> 6 | AS5: =IFERROR(IF(_xlfn.XLOOKUP(B5,'w7'!$B:$B,'w7'!$G:$G)="--",0,_xlfn.XLOOKUP(B5,'w7'!$B:$B,'w7'!$G:$G)),0) -> 126 | AT5: =_xlfn.RANK.EQ(AS5,AS$3:AS$10000,0) -> 46 | AU5: =IFERROR(_xlfn.XLOOKUP(B5,'w8'!$B:$B,'w8'!$C:$C),0) -> 17.2 | AV5: =_xlfn.RANK.EQ(AU5,AU$3:AU$10000,0) -> 54 | AW5: =IFERROR(_xlfn.XLOOKUP(B5,'w8'!$B:$B,'w8'!$F:$F),1) -> 0.25972222 | AX5: =_xlfn.RANK.EQ(AW5,AW$3:AW$10000,1) -> 24 | AY5: =IFERROR(IF(_xlfn.XLOOKUP(B5,'w8'!$B:$B,'w8'!$G:$G)="--",0,_xlfn.XLOOKUP(B5,'w8'!$B:$B,'w8'!$G:$G)),0) -> 29 | AZ5: =_xlfn.RANK.EQ(AY5,AY$3:AY$10000,0) -> 63 | BA5: =IFERROR(_xlfn.XLOOKUP(C5,'w9'!$B:$B,'w9'!$C:$C),0) -> 42.5 | BB5: =_xlfn.RANK.EQ(BA5,BA$3:BA$10000,0) -> 21 | BC5: =IFERROR(_xlfn.XLOOKUP(C5,'w9'!$B:$B,'w9'!$F:$F),1) -> 0.27361111 | BD5: =_xlfn.RANK.EQ(BC5,BC$3:BC$10000,1) -> 25 | BE5: =IFERROR(IF(_xlfn.XLOOKUP(C5,'w9'!$B:$B,'w9'!$G:$G)="--",0,_xlfn.XLOOKUP(C5,'w9'!$B:$B,'w9'!$G:$G)),0) -> 307 | BF5: =_xlfn.RANK.EQ(BE5,BE$3:BE$10000,0) -> 43 | BG5: =IFERROR(_xlfn.XLOOKUP(B5,'w10'!$B:$B,'w10'!$C:$C),0) -> 55.2 | BH5: =_xlfn.RANK.EQ(BG5,BG$3:BG$10000,0) -> 8 | BI5: =IFERROR(_xlfn.XLOOKUP(B5,'w10'!$B:$B,'w10'!$F:$F),1) -> 0.2625 | BJ5: =_xlfn.RANK.EQ(BI5,BI$3:BI$10000,1) -> 31 | BK5: =IFERROR(IF(_xlfn.XLOOKUP(B5,'w10'!$B:$B,'w10'!$G:$G)="--",0,_xlfn.XLOOKUP(B5,'w10'!$B:$B,'w10'!$G:$G)),0) -> 720 | BL5: =_xlfn.RANK.EQ(BK5,BK$3:BK$10000,0) -> 16 | BM5: =IFERROR(_xlfn.XLOOKUP(B5,'w11'!$B:$B,'w11'!$C:$C),0) -> 58.9 | BN5: =_xlfn.RANK.EQ(BM5,BM$3:BM$10000,0) -> 6 | BO5: =IFERROR(_xlfn.XLOOKUP(B5,'w11'!$B:$B,'w11'!$F:$F),1) -> 0.26527778 | BP5: =_xlfn.RANK.EQ(BO5,BO$3:BO$10000,1) -> 33 | BQ5: =IFERROR(IF(_xlfn.XLOOKUP(B5,'w11'!$B:$B,'w11'!$G:$G)="--",0,_xlfn.XLOOKUP(B5,'w11'!$B:$B,'w11'!$G:$G)),0) -> 680 | BR5: =_xlfn.RANK.EQ(BQ5,BQ$3:BQ$10000,0) -> 12 | BS5: =IFERROR(_xlfn.XLOOKUP(B5,'w12'!$B:$B,'w12'!$C:$C),0) -> 85.6 | BT5: =_xlfn.RANK.EQ(BS5,BS$3:BS$10000,0) -> 3 | BU5: =IFERROR(_xlfn.XLOOKUP(B5,'w12'!$B:$B,'w12'!$F:$F),1) -> 0.25763889 | BV5: =_xlfn.RANK.EQ(BU5,BU$3:BU$10000,1) -> 23 | BW5: =IFERROR(IF(_xlfn.XLOOKUP(B5,'w12'!$B:$B,'w12'!$G:$G)="--",0,_xlfn.XLOOKUP(B5,'w12'!$B:$B,'w12'!$G:$G)),0) -> 1059 | BX5: =_xlfn.RANK.EQ(BW5,BW$3:BW$10000,0) -> 7 | BY5: =IFERROR(_xlfn.XLOOKUP(B5,'w13'!$B:$B,'w13'!$C:$C),0) -> 64.5 | BZ5: =_xlfn.RANK.EQ(BY5,BY$3:BY$10000,0) -> 7 | CA5: =IFERROR(_xlfn.XLOOKUP(B5,'w13'!$B:$B,'w13'!$F:$F),1) -> 0.25416667 | CB5: =_xlfn.RANK.EQ(CA5,CA$3:CA$10000,1) -> 26 | CC5: =IFERROR(IF(_xlfn.XLOOKUP(B5,'w13'!$B:$B,'w13'!$G:$G)="--",0,_xlfn.XLOOKUP(B5,'w13'!$B:$B,'w13'!$G:$G)),0) -> 777 | CD5: =_xlfn.RANK.EQ(CC5,CC$3:CC$10000,0) -> 13 | CE5: =IFERROR(_xlfn.XLOOKUP(B5,'w14'!$B:$B,'w14'!$C:$C),0) -> 65 | CF5: =_xlfn.RANK.EQ(CE5,CE$3:CE$10000,0) -> 6 | CG5: =IFERROR(_xlfn.XLOOKUP(B5,'w14'!$B:$B,'w14'!$F:$F),1) -> 0.25486111 | CH5: =_xlfn.RANK.EQ(CG5,CG$3:CG$10000,1) -> 16 | CI5: =IFERROR(IF(_xlfn.XLOOKUP(B5,'w14'!$B:$B,'w14'!$G:$G)="--",0,_xlfn.XLOOKUP(B5,'w14'!$B:$B,'w14'!$G:$G)),0) -> 621 | CJ5: =_xlfn.RANK.EQ(CI5,CI$3:CI$10000,0) -> 18 | CK5: =_xlfn.RANK.EQ(D5,D$3:D$10000,1) -> 3 | CL5: Carlos Vaz Vignolo | CM5: =SUM(E5,K5,Q5,W5,AC5,AI5,AO5,AU5,BA5,BG5,BM5,BS5,BY5,CE5) -> 863 | CN5: =_xlfn.RANK.EQ(CM5,CM$3:CM$10000) -> 3 | CO5: =IFERROR(SUM(PRODUCT(E5,G5),PRODUCT(K5,M5),PRODUCT(Q5,S5),PRODUCT(W5,Y5),PRODUCT(AC5,AE5),PRODUCT(AI5,AK5),PRODUCT(AO5,AQ5),PRODUCT(AU5,AW5),PRODUCT(BA5,BC5),PRODUCT(BG5,BI5),PRODUCT(BM5,BO5),PRODUCT(BS5,BU5),PRODUCT(BY5,CA5),PRODUCT(CE5,CG5))/CM5,1) -> 0.25695708 | CP5: =_xlfn.RANK.EQ(CO5,CO$3:CO$10000,1) -> 25 | CQ5: =SUM(I5,O5,U5,AA5,AG5,AM5,AS5,AY5,BE5,BK5,BQ5,BW5,CC5,CI5) -> 8609 | CR5: =_xlfn.RANK.EQ(CQ5,CQ$3:CQ$10000) -> 16 | CS5: =_xlfn.RANK.EQ(CT5,CT$3:CT$10000,1) -> 18 | CT5: =CV5*$CN$1+CX5*$CP$1+CZ5*$CR$1 -> 49.45 | CU5: =_xlfn.STDEV.S(F5,L5,R5,X5,AD5,AJ5,AP5,AV5,BB5,BH5,BN5,BT5,BZ5,CF5) -> 13.627904 | CV5: =_xlfn.RANK.EQ(CU5,CU$3:CU$10000,1) -> 50 | CW5: =_xlfn.STDEV.S(H5,N5,T5,Z5,AF5,AL5,AR5,AX5,BD5,BJ5,BP5,BV5,CB5,CH5) -> 7.0652376 | CX5: =_xlfn.RANK.EQ(CW5,CW$3:CW$10000,1) -> 13 | CY5: =_xlfn.STDEV.S(J5,P5,V5,AB5,AH5,AN5,AT5,AZ5,BF5,BL5,BR5,BX5,CD5,CJ5) -> 16.925986 | CZ5: =_xlfn.RANK.EQ(CY5,CY$3:CY$10000,1) -> 65 | DA5: =SUM(COUNTIF(E5,">0"),COUNTIF(K5,">0"),COUNTIF(Q5,">0"),COUNTIF(W5,">0"),COUNTIF(AC5,">0"),COUNTIF(AI5,">0"),COUNTIF(AO5,">0"),COUNTIF(AU5,">0"),COUNTIF(BA5,">0"),COUNTIF(BG5,">0"),COUNTIF(BM5,">0"),COUNTIF(BS5,">0"),COUNTIF(BY5,">0"),COUNTIF(CE5,">0")) -> 14
B6: João Veiga João Veiga | C6: João Veiga | D6: =CN6*$CN$1+CP6*$CP$1+CR6*$CR$1 -> 4.85 | E6: =IFERROR(_xlfn.XLOOKUP(B6,'w1'!$B:$B,'w1'!$C:$C),0) -> 56.7 | F6: =_xlfn.RANK.EQ(E6,E$3:E$10000,0) -> 7 | G6: =IFERROR(_xlfn.XLOOKUP(B6,'w1'!$B:$B,'w1'!$F:$F),1) -> 0.22291667 | H6: =_xlfn.RANK.EQ(G6,G$3:G$10000,1) -> 7 | I6: =IFERROR(IF(_xlfn.XLOOKUP(B6,'w1'!$B:$B,'w1'!$G:$G)="--",0,_xlfn.XLOOKUP(B6,'w1'!$B:$B,'w1'!$G:$G)),0) -> 328 | J6: =_xlfn.RANK.EQ(I6,I$3:I$10000,0) -> 28 | K6: =IFERROR(_xlfn.XLOOKUP(B6,'w2'!$B:$B,'w2'!$C:$C),0) -> 93.2 | L6: =_xlfn.RANK.EQ(K6,K$3:K$10000,0) -> 2 | M6: =IFERROR(_xlfn.XLOOKUP(B6,'w2'!$B:$B,'w2'!$F:$F),1) -> 0.23333333 | N6: =_xlfn.RANK.EQ(M6,M$3:M$10000,1) -> 6 | O6: =IFERROR(IF(_xlfn.XLOOKUP(B6,'w2'!$B:$B,'w2'!$G:$G)="--",0,_xlfn.XLOOKUP(B6,'w2'!$B:$B,'w2'!$G:$G)),0) -> 190 | P6: =_xlfn.RANK.EQ(O6,O$3:O$10000,0) -> 40 | Q6: =IFERROR(_xlfn.XLOOKUP(B6,'w3'!$B:$B,'w3'!$C:$C),0) -> 44.5 | R6: =_xlfn.RANK.EQ(Q6,Q$3:Q$10000,0) -> 16 | S6: =IFERROR(_xlfn.XLOOKUP(B6,'w3'!$B:$B,'w3'!$F:$F),1) -> 0.22708333 | T6: =_xlfn.RANK.EQ(S6,S$3:S$10000,1) -> 4 | U6: =IFERROR(IF(_xlfn.XLOOKUP(B6,'w3'!$B:$B,'w3'!$G:$G)="--",0,_xlfn.XLOOKUP(B6,'w3'!$B:$B,'w3'!$G:$G)),0) -> 165 | V6: =_xlfn.RANK.EQ(U6,U$3:U$10000,0) -> 40 | W6: =IFERROR(_xlfn.XLOOKUP(B6,'w4'!$B:$B,'w4'!$C:$C),0) -> 56.2 | X6: =_xlfn.RANK.EQ(W6,W$3:W$10000,0) -> 8 | Y6: =IFERROR(_xlfn.XLOOKUP(B6,'w4'!$B:$B,'w4'!$F:$F),1) -> 0.21111111 | Z6: =_xlfn.RANK.EQ(Y6,Y$3:Y$10000,1) -> 4 | AA6: =IFERROR(IF(_xlfn.XLOOKUP(B6,'w4'!$B:$B,'w4'!$G:$G)="--",0,_xlfn.XLOOKUP(B6,'w4'!$B:$B,'w4'!$G:$G)),0) -> 304 | AB6: =_xlfn.RANK.EQ(AA6,AA$3:AA$10000,0) -> 26 | AC6: =IFERROR(_xlfn.XLOOKUP(B6,'w5'!$B:$B,'w5'!$C:$C),0) -> 52.4 | AD6: =_xlfn.RANK.EQ(AC6,AC$3:AC$10000,0) -> 7 | AE6: =IFERROR(_xlfn.XLOOKUP(B6,'w5'!$B:$B,'w5'!$F:$F),1) -> 0.21666667 | AF6: =_xlfn.RANK.EQ(AE6,AE$3:AE$10000,1) -> 4 | AG6: =IFERROR(IF(_xlfn.XLOOKUP(B6,'w5'!$B:$B,'w5'!$G:$G)="--",0,_xlfn.XLOOKUP(B6,'w5'!$B:$B,'w5'!$G:$G)),0) -> 280 | AH6: =_xlfn.RANK.EQ(AG6,AG$3:AG$10000,0) -> 34 | AI6: =IFERROR(_xlfn.XLOOKUP(B6,'w6'!$B:$B,'w6'!$C:$C),0) -> 62.5 | AJ6: =_xlfn.RANK.EQ(AI6,AI$3:AI$10000,0) -> 4 | AK6: =IFERROR(_xlfn.XLOOKUP(B6,'w6'!$B:$B,'w6'!$F:$F),1) -> 0.21597222 | AL6: =_xlfn.RANK.EQ(AK6,AK$3:AK$10000,1) -> 3 | AM6: =IFERROR(IF(_xlfn.XLOOKUP(B6,'w6'!$B:$B,'w6'!$G:$G)="--",0,_xlfn.XLOOKUP(B6,'w6'!$B:$B,'w6'!$G:$G)),0) -> 362 | AN6: =_xlfn.RANK.EQ(AM6,AM$3:AM$10000,0) -> 19 | AO6: =IFERROR(_xlfn.XLOOKUP(B6,'w7'!$B:$B,'w7'!$C:$C),0) -> 63 | AP6: =_xlfn.RANK.EQ(AO6,AO$3:AO$10000,0) -> 4 | AQ6: =IFERROR(_xlfn.XLOOKUP(B6,'w7'!$B:$B,'w7'!$F:$F),1) -> 0.22361111 | AR6: =_xlfn.RANK.EQ(AQ6,AQ$3:AQ$10000,1) -> 5 | AS6: =IFERROR(IF(_xlfn.XLOOKUP(B6,'w7'!$B:$B,'w7'!$G:$G)="--",0,_xlfn.XLOOKUP(B6,'w7'!$B:$B,'w7'!$G:$G)),0) -> 145 | AT6: =_xlfn.RANK.EQ(AS6,AS$3:AS$10000,0) -> 42 | AU6: =IFERROR(_xlfn.XLOOKUP(B6,'w8'!$B:$B,'w8'!$C:$C),0) -> 52.7 | AV6: =_xlfn.RANK.EQ(AU6,AU$3:AU$10000,0) -> 10 | AW6: =IFERROR(_xlfn.XLOOKUP(B6,'w8'!$B:$B,'w8'!$F:$F),1) -> 0.22638889 | AX6: =_xlfn.RANK.EQ(AW6,AW$3:AW$10000,1) -> 6 | AY6: =IFERROR(IF(_xlfn.XLOOKUP(B6,'w8'!$B:$B,'w8'!$G:$G)="--",0,_xlfn.XLOOKUP(B6,'w8'!$B:$B,'w8'!$G:$G)),0) -> 236 | AZ6: =_xlfn.RANK.EQ(AY6,AY$3:AY$10000,0) -> 36 | BA6: =IFERROR(_xlfn.XLOOKUP(C6,'w9'!$B:$B,'w9'!$C:$C),0) -> 57.4 | BB6: =_xlfn.RANK.EQ(BA6,BA$3:BA$10000,0) -> 8 | BC6: =IFERROR(_xlfn.XLOOKUP(C6,'w9'!$B:$B,'w9'!$F:$F),1) -> 0.22013889 | BD6: =_xlfn.RANK.EQ(BC6,BC$3:BC$10000,1) -> 4 | BE6: =IFERROR(IF(_xlfn.XLOOKUP(C6,'w9'!$B:$B,'w9'!$G:$G)="--",0,_xlfn.XLOOKUP(C6,'w9'!$B:$B,'w9'!$G:$G)),0) -> 368 | BF6: =_xlfn.RANK.EQ(BE6,BE$3:BE$10000,0) -> 39 | BG6: =IFERROR(_xlfn.XLOOKUP(B6,'w10'!$B:$B,'w10'!$C:$C),0) -> 67.4 | BH6: =_xlfn.RANK.EQ(BG6,BG$3:BG$10000,0) -> 4 | BI6: =IFERROR(_xlfn.XLOOKUP(B6,'w10'!$B:$B,'w10'!$F:$F),1) -> 0.21736111 | BJ6: =_xlfn.RANK.EQ(BI6,BI$3:BI$10000,1) -> 4 | BK6: =IFERROR(IF(_xlfn.XLOOKUP(B6,'w10'!$B:$B,'w10'!$G:$G)="--",0,_xlfn.XLOOKUP(B6,'w10'!$B:$B,'w10'!$G:$G)),0) -> 330 | BL6: =_xlfn.RANK.EQ(BK6,BK$3:BK$10000,0) -> 22 | BM6: =IFERROR(_xlfn.XLOOKUP(B6,'w11'!$B:$B,'w11'!$C:$C),0) -> 36.8 | BN6: =_xlfn.RANK.EQ(BM6,BM$3:BM$10000,0) -> 20 | BO6: =IFERROR(_xlfn.XLOOKUP(B6,'w11'!$B:$B,'w11'!$F:$F),1) -> 0.21666667 | BP6: =_xlfn.RANK.EQ(BO6,BO$3:BO$10000,1) -> 5 | BQ6: =IFERROR(IF(_xlfn.XLOOKUP(B6,'w11'!$B:$B,'w11'!$G:$G)="--",0,_xlfn.XLOOKUP(B6,'w11'!$B:$B,'w11'!$G:$G)),0) -> 227 | BR6: =_xlfn.RANK.EQ(BQ6,BQ$3:BQ$10000,0) -> 35 | BS6: =IFERROR(_xlfn.XLOOKUP(B6,'w12'!$B:$B,'w12'!$C:$C),0) -> 70.3 | BT6: =_xlfn.RANK.EQ(BS6,BS$3:BS$10000,0) -> 5 | BU6: =IFERROR(_xlfn.XLOOKUP(B6,'w12'!$B:$B,'w12'!$F:$F),1) -> 0.25763889 | BV6: =_xlfn.RANK.EQ(BU6,BU$3:BU$10000,1) -> 23 | BW6: =IFERROR(IF(_xlfn.XLOOKUP(B6,'w12'!$B:$B,'w12'!$G:$G)="--",0,_xlfn.XLOOKUP(B6,'w12'!$B:$B,'w12'!$G:$G)),0) -> 253 | BX6: =_xlfn.RANK.EQ(BW6,BW$3:BW$10000,0) -> 27 | BY6: =IFERROR(_xlfn.XLOOKUP(B6,'w13'!$B:$B,'w13'!$C:$C),0) -> 40.5 | BZ6: =_xlfn.RANK.EQ(BY6,BY$3:BY$10000,0) -> 13 | CA6: =IFERROR(_xlfn.XLOOKUP(B6,'w13'!$B:$B,'w13'!$F:$F),1) -> 0.22847222 | CB6: =_xlfn.RANK.EQ(CA6,CA$3:CA$10000,1) -> 10 | CC6: =IFERROR(IF(_xlfn.XLOOKUP(B6,'w13'!$B:$B,'w13'!$G:$G)="--",0,_xlfn.XLOOKUP(B6,'w13'!$B:$B,'w13'!$G:$G)),0) -> 206 | CD6: =_xlfn.RANK.EQ(CC6,CC$3:CC$10000,0) -> 36 | CE6: =IFERROR(_xlfn.XLOOKUP(B6,'w14'!$B:$B,'w14'!$C:$C),0) -> 59.1 | CF6: =_xlfn.RANK.EQ(CE6,CE$3:CE$10000,0) -> 8 | CG6: =IFERROR(_xlfn.XLOOKUP(B6,'w14'!$B:$B,'w14'!$F:$F),1) -> 0.22013889 | CH6: =_xlfn.RANK.EQ(CG6,CG$3:CG$10000,1) -> 4 | CI6: =IFERROR(IF(_xlfn.XLOOKUP(B6,'w14'!$B:$B,'w14'!$G:$G)="--",0,_xlfn.XLOOKUP(B6,'w14'!$B:$B,'w14'!$G:$G)),0) -> 242 | CJ6: =_xlfn.RANK.EQ(CI6,CI$3:CI$10000,0) -> 35 | CK6: =_xlfn.RANK.EQ(D6,D$3:D$10000,1) -> 4 | CL6: João Veiga | CM6: =SUM(E6,K6,Q6,W6,AC6,AI6,AO6,AU6,BA6,BG6,BM6,BS6,BY6,CE6) -> 812.7 | CN6: =_xlfn.RANK.EQ(CM6,CM$3:CM$10000) -> 4 | CO6: =IFERROR(SUM(PRODUCT(E6,G6),PRODUCT(K6,M6),PRODUCT(Q6,S6),PRODUCT(W6,Y6),PRODUCT(AC6,AE6),PRODUCT(AI6,AK6),PRODUCT(AO6,AQ6),PRODUCT(AU6,AW6),PRODUCT(BA6,BC6),PRODUCT(BG6,BI6),PRODUCT(BM6,BO6),PRODUCT(BS6,BU6),PRODUCT(BY6,CA6),PRODUCT(CE6,CG6))/CM6,1) -> 0.22500342 | CP6: =_xlfn.RANK.EQ(CO6,CO$3:CO$10000,1) -> 6 | CQ6: =SUM(I6,O6,U6,AA6,AG6,AM6,AS6,AY6,BE6,BK6,BQ6,BW6,CC6,CI6) -> 3636 | CR6: =_xlfn.RANK.EQ(CQ6,CQ$3:CQ$10000) -> 36 | CS6: =_xlfn.RANK.EQ(CT6,CT$3:CT$10000,1) -> 2 | CT6: =CV6*$CN$1+CX6*$CP$1+CZ6*$CR$1 -> 10.925 | CU6: =_xlfn.STDEV.S(F6,L6,R6,X6,AD6,AJ6,AP6,AV6,BB6,BH6,BN6,BT6,BZ6,CF6) -> 5.0448538 | CV6: =_xlfn.RANK.EQ(CU6,CU$3:CU$10000,1) -> 11 | CW6: =_xlfn.STDEV.S(H6,N6,T6,Z6,AF6,AL6,AR6,AX6,BD6,BJ6,BP6,BV6,CB6,CH6) -> 5.1081706 | CX6: =_xlfn.RANK.EQ(CW6,CW$3:CW$10000,1) -> 6 | CY6: =_xlfn.STDEV.S(J6,P6,V6,AB6,AH6,AN6,AT6,AZ6,BF6,BL6,BR6,BX6,CD6,CJ6) -> 7.1702223 | CZ6: =_xlfn.RANK.EQ(CY6,CY$3:CY$10000,1) -> 13 | DA6: =SUM(COUNTIF(E6,">0"),COUNTIF(K6,">0"),COUNTIF(Q6,">0"),COUNTIF(W6,">0"),COUNTIF(AC6,">0"),COUNTIF(AI6,">0"),COUNTIF(AO6,">0"),COUNTIF(AU6,">0"),COUNTIF(BA6,">0"),COUNTIF(BG6,">0"),COUNTIF(BM6,">0"),COUNTIF(BS6,">0"),COUNTIF(BY6,">0"),COUNTIF(CE6,">0")) -> 14
B7: João Abreu João Abreu | C7: João Abreu | D7: =CN7*$CN$1+CP7*$CP$1+CR7*$CR$1 -> 6.275 | E7: =IFERROR(_xlfn.XLOOKUP(B7,'w1'!$B:$B,'w1'!$C:$C),0) -> 76 | F7: =_xlfn.RANK.EQ(E7,E$3:E$10000,0) -> 2 | G7: =IFERROR(_xlfn.XLOOKUP(B7,'w1'!$B:$B,'w1'!$F:$F),1) -> 0.31875 | H7: =_xlfn.RANK.EQ(G7,G$3:G$10000,1) -> 63 | I7: =IFERROR(IF(_xlfn.XLOOKUP(B7,'w1'!$B:$B,'w1'!$G:$G)="--",0,_xlfn.XLOOKUP(B7,'w1'!$B:$B,'w1'!$G:$G)),0) -> 2129 | J7: =_xlfn.RANK.EQ(I7,I$3:I$10000,0) -> 2 | K7: =IFERROR(_xlfn.XLOOKUP(B7,'w2'!$B:$B,'w2'!$C:$C),0) -> 82.8 | L7: =_xlfn.RANK.EQ(K7,K$3:K$10000,0) -> 4 | M7: =IFERROR(_xlfn.XLOOKUP(B7,'w2'!$B:$B,'w2'!$F:$F),1) -> 0.24305556 | N7: =_xlfn.RANK.EQ(M7,M$3:M$10000,1) -> 11 | O7: =IFERROR(IF(_xlfn.XLOOKUP(B7,'w2'!$B:$B,'w2'!$G:$G)="--",0,_xlfn.XLOOKUP(B7,'w2'!$B:$B,'w2'!$G:$G)),0) -> 1850 | P7: =_xlfn.RANK.EQ(O7,O$3:O$10000,0) -> 5 | Q7: =IFERROR(_xlfn.XLOOKUP(B7,'w3'!$B:$B,'w3'!$C:$C),0) -> 94.3 | R7: =_xlfn.RANK.EQ(Q7,Q$3:Q$10000,0) -> 2 | S7: =IFERROR(_xlfn.XLOOKUP(B7,'w3'!$B:$B,'w3'!$F:$F),1) -> 0.29583333 | T7: =_xlfn.RANK.EQ(S7,S$3:S$10000,1) -> 49 | U7: =IFERROR(IF(_xlfn.XLOOKUP(B7,'w3'!$B:$B,'w3'!$G:$G)="--",0,_xlfn.XLOOKUP(B7,'w3'!$B:$B,'w3'!$G:$G)),0) -> 3134 | V7: =_xlfn.RANK.EQ(U7,U$3:U$10000,0) -> 2 | W7: =IFERROR(_xlfn.XLOOKUP(B7,'w4'!$B:$B,'w4'!$C:$C),0) -> 57.6 | X7: =_xlfn.RANK.EQ(W7,W$3:W$10000,0) -> 6 | Y7: =IFERROR(_xlfn.XLOOKUP(B7,'w4'!$B:$B,'w4'!$F:$F),1) -> 0.23680556 | Z7: =_xlfn.RANK.EQ(Y7,Y$3:Y$10000,1) -> 10 | AA7: =IFERROR(IF(_xlfn.XLOOKUP(B7,'w4'!$B:$B,'w4'!$G:$G)="--",0,_xlfn.XLOOKUP(B7,'w4'!$B:$B,'w4'!$G:$G)),0) -> 1701 | AB7: =_xlfn.RANK.EQ(AA7,AA$3:AA$10000,0) -> 5 | AC7: =IFERROR(_xlfn.XLOOKUP(B7,'w5'!$B:$B,'w5'!$C:$C),0) -> 51.5 | AD7: =_xlfn.RANK.EQ(AC7,AC$3:AC$10000,0) -> 8 | AE7: =IFERROR(_xlfn.XLOOKUP(B7,'w5'!$B:$B,'w5'!$F:$F),1) -> 0.26388889 | AF7: =_xlfn.RANK.EQ(AE7,AE$3:AE$10000,1) -> 28 | AG7: =IFERROR(IF(_xlfn.XLOOKUP(B7,'w5'!$B:$B,'w5'!$G:$G)="--",0,_xlfn.XLOOKUP(B7,'w5'!$B:$B,'w5'!$G:$G)),0) -> 751 | AH7: =_xlfn.RANK.EQ(AG7,AG$3:AG$10000,0) -> 19 | AI7: =IFERROR(_xlfn.XLOOKUP(B7,'w6'!$B:$B,'w6'!$C:$C),0) -> 38.7 | AJ7: =_xlfn.RANK.EQ(AI7,AI$3:AI$10000,0) -> 11 | AK7: =IFERROR(_xlfn.XLOOKUP(B7,'w6'!$B:$B,'w6'!$F:$F),1) -> 0.27013889 | AL7: =_xlfn.RANK.EQ(AK7,AK$3:AK$10000,1) -> 25 | AM7: =IFERROR(IF(_xlfn.XLOOKUP(B7,'w6'!$B:$B,'w6'!$G:$G)="--",0,_xlfn.XLOOKUP(B7,'w6'!$B:$B,'w6'!$G:$G)),0) -> 1019 | AN7: =_xlfn.RANK.EQ(AM7,AM$3:AM$10000,0) -> 5 | AO7: =IFERROR(_xlfn.XLOOKUP(B7,'w7'!$B:$B,'w7'!$C:$C),0) -> 42.6 | AP7: =_xlfn.RANK.EQ(AO7,AO$3:AO$10000,0) -> 16 | AQ7: =IFERROR(_xlfn.XLOOKUP(B7,'w7'!$B:$B,'w7'!$F:$F),1) -> 0.20694444 | AR7: =_xlfn.RANK.EQ(AQ7,AQ$3:AQ$10000,1) -> 3 | AS7: =IFERROR(IF(_xlfn.XLOOKUP(B7,'w7'!$B:$B,'w7'!$G:$G)="--",0,_xlfn.XLOOKUP(B7,'w7'!$B:$B,'w7'!$G:$G)),0) -> 936 | AT7: =_xlfn.RANK.EQ(AS7,AS$3:AS$10000,0) -> 17 | AU7: =IFERROR(_xlfn.XLOOKUP(B7,'w8'!$B:$B,'w8'!$C:$C),0) -> 126.1 | AV7: =_xlfn.RANK.EQ(AU7,AU$3:AU$10000,0) -> 2 | AW7: =IFERROR(_xlfn.XLOOKUP(B7,'w8'!$B:$B,'w8'!$F:$F),1) -> 0.36180556 | AX7: =_xlfn.RANK.EQ(AW7,AW$3:AW$10000,1) -> 63 | AY7: =IFERROR(IF(_xlfn.XLOOKUP(B7,'w8'!$B:$B,'w8'!$G:$G)="--",0,_xlfn.XLOOKUP(B7,'w8'!$B:$B,'w8'!$G:$G)),0) -> 4410 | AZ7: =_xlfn.RANK.EQ(AY7,AY$3:AY$10000,0) -> 1 | BA7: =IFERROR(_xlfn.XLOOKUP(C7,'w9'!$B:$B,'w9'!$C:$C),0) -> 35.7 | BB7: =_xlfn.RANK.EQ(BA7,BA$3:BA$10000,0) -> 28 | BC7: =IFERROR(_xlfn.XLOOKUP(C7,'w9'!$B:$B,'w9'!$F:$F),1) -> 0.24027778 | BD7: =_xlfn.RANK.EQ(BC7,BC$3:BC$10000,1) -> 11 | BE7: =IFERROR(IF(_xlfn.XLOOKUP(C7,'w9'!$B:$B,'w9'!$G:$G)="--",0,_xlfn.XLOOKUP(C7,'w9'!$B:$B,'w9'!$G:$G)),0) -> 910 | BF7: =_xlfn.RANK.EQ(BE7,BE$3:BE$10000,0) -> 8 | BG7: =IFERROR(_xlfn.XLOOKUP(B7,'w10'!$B:$B,'w10'!$C:$C),0) -> 44.5 | BH7: =_xlfn.RANK.EQ(BG7,BG$3:BG$10000,0) -> 17 | BI7: =IFERROR(_xlfn.XLOOKUP(B7,'w10'!$B:$B,'w10'!$F:$F),1) -> 0.33472222 | BJ7: =_xlfn.RANK.EQ(BI7,BI$3:BI$10000,1) -> 63 | BK7: =IFERROR(IF(_xlfn.XLOOKUP(B7,'w10'!$B:$B,'w10'!$G:$G)="--",0,_xlfn.XLOOKUP(B7,'w10'!$B:$B,'w10'!$G:$G)),0) -> 799 | BL7: =_xlfn.RANK.EQ(BK7,BK$3:BK$10000,0) -> 13 | BM7: =IFERROR(_xlfn.XLOOKUP(B7,'w11'!$B:$B,'w11'!$C:$C),0) -> 22.2 | BN7: =_xlfn.RANK.EQ(BM7,BM$3:BM$10000,0) -> 39 | BO7: =IFERROR(_xlfn.XLOOKUP(B7,'w11'!$B:$B,'w11'!$F:$F),1) -> 0.18333333 | BP7: =_xlfn.RANK.EQ(BO7,BO$3:BO$10000,1) -> 1 | BQ7: =IFERROR(IF(_xlfn.XLOOKUP(B7,'w11'!$B:$B,'w11'!$G:$G)="--",0,_xlfn.XLOOKUP(B7,'w11'!$B:$B,'w11'!$G:$G)),0) -> 638 | BR7: =_xlfn.RANK.EQ(BQ7,BQ$3:BQ$10000,0) -> 13 | BS7: =IFERROR(_xlfn.XLOOKUP(B7,'w12'!$B:$B,'w12'!$C:$C),0) -> 14 | BT7: =_xlfn.RANK.EQ(BS7,BS$3:BS$10000,0) -> 49 | BU7: =IFERROR(_xlfn.XLOOKUP(B7,'w12'!$B:$B,'w12'!$F:$F),1) -> 0.22777778 | BV7: =_xlfn.RANK.EQ(BU7,BU$3:BU$10000,1) -> 7 | BW7: =IFERROR(IF(_xlfn.XLOOKUP(B7,'w12'!$B:$B,'w12'!$G:$G)="--",0,_xlfn.XLOOKUP(B7,'w12'!$B:$B,'w12'!$G:$G)),0) -> 379 | BX7: =_xlfn.RANK.EQ(BW7,BW$3:BW$10000,0) -> 15 | BY7: =IFERROR(_xlfn.XLOOKUP(B7,'w13'!$B:$B,'w13'!$C:$C),0) -> 105.3 | BZ7: =_xlfn.RANK.EQ(BY7,BY$3:BY$10000,0) -> 2 | CA7: =IFERROR(_xlfn.XLOOKUP(B7,'w13'!$B:$B,'w13'!$F:$F),1) -> 0.35069444 | CB7: =_xlfn.RANK.EQ(CA7,CA$3:CA$10000,1) -> 59 | CC7: =IFERROR(IF(_xlfn.XLOOKUP(B7,'w13'!$B:$B,'w13'!$G:$G)="--",0,_xlfn.XLOOKUP(B7,'w13'!$B:$B,'w13'!$G:$G)),0) -> 1773 | CD7: =_xlfn.RANK.EQ(CC7,CC$3:CC$10000,0) -> 5 | CE7: =IFERROR(_xlfn.XLOOKUP(B7,'w14'!$B:$B,'w14'!$C:$C),0) -> 0 | CF7: =_xlfn.RANK.EQ(CE7,CE$3:CE$10000,0) -> 69 | CG7: =IFERROR(_xlfn.XLOOKUP(B7,'w14'!$B:$B,'w14'!$F:$F),1) -> 1 | CH7: =_xlfn.RANK.EQ(CG7,CG$3:CG$10000,1) -> 69 | CI7: =IFERROR(IF(_xlfn.XLOOKUP(B7,'w14'!$B:$B,'w14'!$G:$G)="--",0,_xlfn.XLOOKUP(B7,'w14'!$B:$B,'w14'!$G:$G)),0) -> 0 | CJ7: =_xlfn.RANK.EQ(CI7,CI$3:CI$10000,0) -> 69 | CK7: =_xlfn.RANK.EQ(D7,D$3:D$10000,1) -> 5 | CL7: João Abreu | CM7: =SUM(E7,K7,Q7,W7,AC7,AI7,AO7,AU7,BA7,BG7,BM7,BS7,BY7,CE7) -> 791.3 | CN7: =_xlfn.RANK.EQ(CM7,CM$3:CM$10000) -> 5 | CO7: =IFERROR(SUM(PRODUCT(E7,G7),PRODUCT(K7,M7),PRODUCT(Q7,S7),PRODUCT(W7,Y7),PRODUCT(AC7,AE7),PRODUCT(AI7,AK7),PRODUCT(AO7,AQ7),PRODUCT(AU7,AW7),PRODUCT(BA7,BC7),PRODUCT(BG7,BI7),PRODUCT(BM7,BO7),PRODUCT(BS7,BU7),PRODUCT(BY7,CA7),PRODUCT(CE7,CG7))/CM7,1) -> 0.293228 | CP7: =_xlfn.RANK.EQ(CO7,CO$3:CO$10000,1) -> 55 | CQ7: =SUM(I7,O7,U7,AA7,AG7,AM7,AS7,AY7,BE7,BK7,BQ7,BW7,CC7,CI7) -> 20429 | CR7: =_xlfn.RANK.EQ(CQ7,CQ$3:CQ$10000) -> 6 | CS7: =_xlfn.RANK.EQ(CT7,CT$3:CT$10000,1) -> 32 | CT7: =CV7*$CN$1+CX7*$CP$1+CZ7*$CR$1 -> 89.75 | CU7: =_xlfn.STDEV.S(F7,L7,R7,X7,AD7,AJ7,AP7,AV7,BB7,BH7,BN7,BT7,BZ7,CF7) -> 20.792671 | CV7: =_xlfn.RANK.EQ(CU7,CU$3:CU$10000,1) -> 90 | CW7: =_xlfn.STDEV.S(H7,N7,T7,Z7,AF7,AL7,AR7,AX7,BD7,BJ7,BP7,BV7,CB7,CH7) -> 26.477857 | CX7: =_xlfn.RANK.EQ(CW7,CW$3:CW$10000,1) -> 100 | CY7: =_xlfn.STDEV.S(J7,P7,V7,AB7,AH7,AN7,AT7,AZ7,BF7,BL7,BR7,BX7,CD7,CJ7) -> 17.227789 | CZ7: =_xlfn.RANK.EQ(CY7,CY$3:CY$10000,1) -> 70 | DA7: =SUM(COUNTIF(E7,">0"),COUNTIF(K7,">0"),COUNTIF(Q7,">0"),COUNTIF(W7,">0"),COUNTIF(AC7,">0"),COUNTIF(AI7,">0"),COUNTIF(AO7,">0"),COUNTIF(AU7,">0"),COUNTIF(BA7,">0"),COUNTIF(BG7,">0"),COUNTIF(BM7,">0"),COUNTIF(BS7,">0"),COUNTIF(BY7,">0"),COUNTIF(CE7,">0")) -> 13
B8: Carmen Ferreira Carmen Ferreira | C8: Carmen Ferreira | D8: =CN8*$CN$1+CP8*$CP$1+CR8*$CR$1 -> 7.875 | E8: =IFERROR(_xlfn.XLOOKUP(B8,'w1'!$B:$B,'w1'!$C:$C),0) -> 64.4 | F8: =_xlfn.RANK.EQ(E8,E$3:E$10000,0) -> 3 | G8: =IFERROR(_xlfn.XLOOKUP(B8,'w1'!$B:$B,'w1'!$F:$F),1) -> 0.3875 | H8: =_xlfn.RANK.EQ(G8,G$3:G$10000,1) -> 75 | I8: =IFERROR(IF(_xlfn.XLOOKUP(B8,'w1'!$B:$B,'w1'!$G:$G)="--",0,_xlfn.XLOOKUP(B8,'w1'!$B:$B,'w1'!$G:$G)),0) -> 2493 | J8: =_xlfn.RANK.EQ(I8,I$3:I$10000,0) -> 1 | K8: =IFERROR(_xlfn.XLOOKUP(B8,'w2'!$B:$B,'w2'!$C:$C),0) -> 40.9 | L8: =_xlfn.RANK.EQ(K8,K$3:K$10000,0) -> 16 | M8: =IFERROR(_xlfn.XLOOKUP(B8,'w2'!$B:$B,'w2'!$F:$F),1) -> 0.35138889 | N8: =_xlfn.RANK.EQ(M8,M$3:M$10000,1) -> 63 | O8: =IFERROR(IF(_xlfn.XLOOKUP(B8,'w2'!$B:$B,'w2'!$G:$G)="--",0,_xlfn.XLOOKUP(B8,'w2'!$B:$B,'w2'!$G:$G)),0) -> 1467 | P8: =_xlfn.RANK.EQ(O8,O$3:O$10000,0) -> 6 | Q8: =IFERROR(_xlfn.XLOOKUP(B8,'w3'!$B:$B,'w3'!$C:$C),0) -> 52.2 | R8: =_xlfn.RANK.EQ(Q8,Q$3:Q$10000,0) -> 11 | S8: =IFERROR(_xlfn.XLOOKUP(B8,'w3'!$B:$B,'w3'!$F:$F),1) -> 0.34166667 | T8: =_xlfn.RANK.EQ(S8,S$3:S$10000,1) -> 68 | U8: =IFERROR(IF(_xlfn.XLOOKUP(B8,'w3'!$B:$B,'w3'!$G:$G)="--",0,_xlfn.XLOOKUP(B8,'w3'!$B:$B,'w3'!$G:$G)),0) -> 1774 | V8: =_xlfn.RANK.EQ(U8,U$3:U$10000,0) -> 5 | W8: =IFERROR(_xlfn.XLOOKUP(B8,'w4'!$B:$B,'w4'!$C:$C),0) -> 37.9 | X8: =_xlfn.RANK.EQ(W8,W$3:W$10000,0) -> 17 | Y8: =IFERROR(_xlfn.XLOOKUP(B8,'w4'!$B:$B,'w4'!$F:$F),1) -> 0.28819444 | Z8: =_xlfn.RANK.EQ(Y8,Y$3:Y$10000,1) -> 43 | AA8: =IFERROR(IF(_xlfn.XLOOKUP(B8,'w4'!$B:$B,'w4'!$G:$G)="--",0,_xlfn.XLOOKUP(B8,'w4'!$B:$B,'w4'!$G:$G)),0) -> 403 | AB8: =_xlfn.RANK.EQ(AA8,AA$3:AA$10000,0) -> 20 | AC8: =IFERROR(_xlfn.XLOOKUP(B8,'w5'!$B:$B,'w5'!$C:$C),0) -> 39.8 | AD8: =_xlfn.RANK.EQ(AC8,AC$3:AC$10000,0) -> 25 | AE8: =IFERROR(_xlfn.XLOOKUP(B8,'w5'!$B:$B,'w5'!$F:$F),1) -> 0.38958333 | AF8: =_xlfn.RANK.EQ(AE8,AE$3:AE$10000,1) -> 64 | AG8: =IFERROR(IF(_xlfn.XLOOKUP(B8,'w5'!$B:$B,'w5'!$G:$G)="--",0,_xlfn.XLOOKUP(B8,'w5'!$B:$B,'w5'!$G:$G)),0) -> 1998 | AH8: =_xlfn.RANK.EQ(AG8,AG$3:AG$10000,0) -> 4 | AI8: =IFERROR(_xlfn.XLOOKUP(B8,'w6'!$B:$B,'w6'!$C:$C),0) -> 31.7 | AJ8: =_xlfn.RANK.EQ(AI8,AI$3:AI$10000,0) -> 16 | AK8: =IFERROR(_xlfn.XLOOKUP(B8,'w6'!$B:$B,'w6'!$F:$F),1) -> 0.29583333 | AL8: =_xlfn.RANK.EQ(AK8,AK$3:AK$10000,1) -> 37 | AM8: =IFERROR(IF(_xlfn.XLOOKUP(B8,'w6'!$B:$B,'w6'!$G:$G)="--",0,_xlfn.XLOOKUP(B8,'w6'!$B:$B,'w6'!$G:$G)),0) -> 873 | AN8: =_xlfn.RANK.EQ(AM8,AM$3:AM$10000,0) -> 8 | AO8: =IFERROR(_xlfn.XLOOKUP(B8,'w7'!$B:$B,'w7'!$C:$C),0) -> 48.6 | AP8: =_xlfn.RANK.EQ(AO8,AO$3:AO$10000,0) -> 11 | AQ8: =IFERROR(_xlfn.XLOOKUP(B8,'w7'!$B:$B,'w7'!$F:$F),1) -> 0.35625 | AR8: =_xlfn.RANK.EQ(AQ8,AQ$3:AQ$10000,1) -> 55 | AS8: =IFERROR(IF(_xlfn.XLOOKUP(B8,'w7'!$B:$B,'w7'!$G:$G)="--",0,_xlfn.XLOOKUP(B8,'w7'!$B:$B,'w7'!$G:$G)),0) -> 1975 | AT8: =_xlfn.RANK.EQ(AS8,AS$3:AS$10000,0) -> 2 | AU8: =IFERROR(_xlfn.XLOOKUP(B8,'w8'!$B:$B,'w8'!$C:$C),0) -> 119.9 | AV8: =_xlfn.RANK.EQ(AU8,AU$3:AU$10000,0) -> 3 | AW8: =IFERROR(_xlfn.XLOOKUP(B8,'w8'!$B:$B,'w8'!$F:$F),1) -> 0.39444444 | AX8: =_xlfn.RANK.EQ(AW8,AW$3:AW$10000,1) -> 67 | AY8: =IFERROR(IF(_xlfn.XLOOKUP(B8,'w8'!$B:$B,'w8'!$G:$G)="--",0,_xlfn.XLOOKUP(B8,'w8'!$B:$B,'w8'!$G:$G)),0) -> 4181 | AZ8: =_xlfn.RANK.EQ(AY8,AY$3:AY$10000,0) -> 2 | BA8: =IFERROR(_xlfn.XLOOKUP(C8,'w9'!$B:$B,'w9'!$C:$C),0) -> 67 | BB8: =_xlfn.RANK.EQ(BA8,BA$3:BA$10000,0) -> 6 | BC8: =IFERROR(_xlfn.XLOOKUP(C8,'w9'!$B:$B,'w9'!$F:$F),1) -> 0.32986111 | BD8: =_xlfn.RANK.EQ(BC8,BC$3:BC$10000,1) -> 55 | BE8: =IFERROR(IF(_xlfn.XLOOKUP(C8,'w9'!$B:$B,'w9'!$G:$G)="--",0,_xlfn.XLOOKUP(C8,'w9'!$B:$B,'w9'!$G:$G)),0) -> 1854 | BF8: =_xlfn.RANK.EQ(BE8,BE$3:BE$10000,0) -> 3 | BG8: =IFERROR(_xlfn.XLOOKUP(B8,'w10'!$B:$B,'w10'!$C:$C),0) -> 65.9 | BH8: =_xlfn.RANK.EQ(BG8,BG$3:BG$10000,0) -> 5 | BI8: =IFERROR(_xlfn.XLOOKUP(B8,'w10'!$B:$B,'w10'!$F:$F),1) -> 0.35 | BJ8: =_xlfn.RANK.EQ(BI8,BI$3:BI$10000,1) -> 68 | BK8: =IFERROR(IF(_xlfn.XLOOKUP(B8,'w10'!$B:$B,'w10'!$G:$G)="--",0,_xlfn.XLOOKUP(B8,'w10'!$B:$B,'w10'!$G:$G)),0) -> 2931 | BL8: =_xlfn.RANK.EQ(BK8,BK$3:BK$10000,0) -> 1 | BM8: =IFERROR(_xlfn.XLOOKUP(B8,'w11'!$B:$B,'w11'!$C:$C),0) -> 20.1 | BN8: =_xlfn.RANK.EQ(BM8,BM$3:BM$10000,0) -> 45 | BO8: =IFERROR(_xlfn.XLOOKUP(B8,'w11'!$B:$B,'w11'!$F:$F),1) -> 0.2625 | BP8: =_xlfn.RANK.EQ(BO8,BO$3:BO$10000,1) -> 29 | BQ8: =IFERROR(IF(_xlfn.XLOOKUP(B8,'w11'!$B:$B,'w11'!$G:$G)="--",0,_xlfn.XLOOKUP(B8,'w11'!$B:$B,'w11'!$G:$G)),0) -> 211 | BR8: =_xlfn.RANK.EQ(BQ8,BQ$3:BQ$10000,0) -> 40 | BS8: =IFERROR(_xlfn.XLOOKUP(B8,'w12'!$B:$B,'w12'!$C:$C),0) -> 59 | BT8: =_xlfn.RANK.EQ(BS8,BS$3:BS$10000,0) -> 6 | BU8: =IFERROR(_xlfn.XLOOKUP(B8,'w12'!$B:$B,'w12'!$F:$F),1) -> 0.32847222 | BV8: =_xlfn.RANK.EQ(BU8,BU$3:BU$10000,1) -> 59 | BW8: =IFERROR(IF(_xlfn.XLOOKUP(B8,'w12'!$B:$B,'w12'!$G:$G)="--",0,_xlfn.XLOOKUP(B8,'w12'!$B:$B,'w12'!$G:$G)),0) -> 1713 | BX8: =_xlfn.RANK.EQ(BW8,BW$3:BW$10000,0) -> 5 | BY8: =IFERROR(_xlfn.XLOOKUP(B8,'w13'!$B:$B,'w13'!$C:$C),0) -> 66.1 | BZ8: =_xlfn.RANK.EQ(BY8,BY$3:BY$10000,0) -> 5 | CA8: =IFERROR(_xlfn.XLOOKUP(B8,'w13'!$B:$B,'w13'!$F:$F),1) -> 0.34861111 | CB8: =_xlfn.RANK.EQ(CA8,CA$3:CA$10000,1) -> 58 | CC8: =IFERROR(IF(_xlfn.XLOOKUP(B8,'w13'!$B:$B,'w13'!$G:$G)="--",0,_xlfn.XLOOKUP(B8,'w13'!$B:$B,'w13'!$G:$G)),0) -> 1924 | CD8: =_xlfn.RANK.EQ(CC8,CC$3:CC$10000,0) -> 4 | CE8: =IFERROR(_xlfn.XLOOKUP(B8,'w14'!$B:$B,'w14'!$C:$C),0) -> 39.8 | CF8: =_xlfn.RANK.EQ(CE8,CE$3:CE$10000,0) -> 20 | CG8: =IFERROR(_xlfn.XLOOKUP(B8,'w14'!$B:$B,'w14'!$F:$F),1) -> 0.36875 | CH8: =_xlfn.RANK.EQ(CG8,CG$3:CG$10000,1) -> 58 | CI8: =IFERROR(IF(_xlfn.XLOOKUP(B8,'w14'!$B:$B,'w14'!$G:$G)="--",0,_xlfn.XLOOKUP(B8,'w14'!$B:$B,'w14'!$G:$G)),0) -> 1612 | CJ8: =_xlfn.RANK.EQ(CI8,CI$3:CI$10000,0) -> 7 | CK8: =_xlfn.RANK.EQ(D8,D$3:D$10000,1) -> 6 | CL8: Carmen Ferreira | CM8: =SUM(E8,K8,Q8,W8,AC8,AI8,AO8,AU8,BA8,BG8,BM8,BS8,BY8,CE8) -> 753.3 | CN8: =_xlfn.RANK.EQ(CM8,CM$3:CM$10000) -> 6 | CO8: =IFERROR(SUM(PRODUCT(E8,G8),PRODUCT(K8,M8),PRODUCT(Q8,S8),PRODUCT(W8,Y8),PRODUCT(AC8,AE8),PRODUCT(AI8,AK8),PRODUCT(AO8,AQ8),PRODUCT(AU8,AW8),PRODUCT(BA8,BC8),PRODUCT(BG8,BI8),PRODUCT(BM8,BO8),PRODUCT(BS8,BU8),PRODUCT(BY8,CA8),PRODUCT(CE8,CG8))/CM8,1) -> 0.35194026 | CP8: =_xlfn.RANK.EQ(CO8,CO$3:CO$10000,1) -> 85 | CQ8: =SUM(I8,O8,U8,AA8,AG8,AM8,AS8,AY8,BE8,BK8,BQ8,BW8,CC8,CI8) -> 25409 | CR8: =_xlfn.RANK.EQ(CQ8,CQ$3:CQ$10000) -> 2 | CS8: =_xlfn.RANK.EQ(CT8,CT$3:CT$10000,1) -> 9 | CT8: =CV8*$CN$1+CX8*$CP$1+CZ8*$CR$1 -> 36.925 | CU8: =_xlfn.STDEV.S(F8,L8,R8,X8,AD8,AJ8,AP8,AV8,BB8,BH8,BN8,BT8,BZ8,CF8) -> 11.373045 | CV8: =_xlfn.RANK.EQ(CU8,CU$3:CU$10000,1) -> 37 | CW8: =_xlfn.STDEV.S(H8,N8,T8,Z8,AF8,AL8,AR8,AX8,BD8,BJ8,BP8,BV8,CB8,CH8) -> 12.845019 | CX8: =_xlfn.RANK.EQ(CW8,CW$3:CW$10000,1) -> 41 | CY8: =_xlfn.STDEV.S(J8,P8,V8,AB8,AH8,AN8,AT8,AZ8,BF8,BL8,BR8,BX8,CD8,CJ8) -> 10.43978 | CZ8: =_xlfn.RANK.EQ(CY8,CY$3:CY$10000,1) -> 30 | DA8: =SUM(COUNTIF(E8,">0"),COUNTIF(K8,">0"),COUNTIF(Q8,">0"),COUNTIF(W8,">0"),COUNTIF(AC8,">0"),COUNTIF(AI8,">0"),COUNTIF(AO8,">0"),COUNTIF(AU8,">0"),COUNTIF(BA8,">0"),COUNTIF(BG8,">0"),COUNTIF(BM8,">0"),COUNTIF(BS8,">0"),COUNTIF(BY8,">0"),COUNTIF(CE8,">0")) -> 14
B9: Marina Marques Marina Marques | C9: Marina Marques | D9: =CN9*$CN$1+CP9*$CP$1+CR9*$CR$1 -> 8.575 | E9: =IFERROR(_xlfn.XLOOKUP(B9,'w1'!$B:$B,'w1'!$C:$C),0) -> 25.3 | F9: =_xlfn.RANK.EQ(E9,E$3:E$10000,0) -> 31 | G9: =IFERROR(_xlfn.XLOOKUP(B9,'w1'!$B:$B,'w1'!$F:$F),1) -> 0.24652778 | H9: =_xlfn.RANK.EQ(G9,G$3:G$10000,1) -> 16 | I9: =IFERROR(IF(_xlfn.XLOOKUP(B9,'w1'!$B:$B,'w1'!$G:$G)="--",0,_xlfn.XLOOKUP(B9,'w1'!$B:$B,'w1'!$G:$G)),0) -> 175 | J9: =_xlfn.RANK.EQ(I9,I$3:I$10000,0) -> 47 | K9: =IFERROR(_xlfn.XLOOKUP(B9,'w2'!$B:$B,'w2'!$C:$C),0) -> 49.1 | L9: =_xlfn.RANK.EQ(K9,K$3:K$10000,0) -> 10 | M9: =IFERROR(_xlfn.XLOOKUP(B9,'w2'!$B:$B,'w2'!$F:$F),1) -> 0.34375 | N9: =_xlfn.RANK.EQ(M9,M$3:M$10000,1) -> 61 | O9: =IFERROR(IF(_xlfn.XLOOKUP(B9,'w2'!$B:$B,'w2'!$G:$G)="--",0,_xlfn.XLOOKUP(B9,'w2'!$B:$B,'w2'!$G:$G)),0) -> 1965 | P9: =_xlfn.RANK.EQ(O9,O$3:O$10000,0) -> 4 | Q9: =IFERROR(_xlfn.XLOOKUP(B9,'w3'!$B:$B,'w3'!$C:$C),0) -> 32.7 | R9: =_xlfn.RANK.EQ(Q9,Q$3:Q$10000,0) -> 27 | S9: =IFERROR(_xlfn.XLOOKUP(B9,'w3'!$B:$B,'w3'!$F:$F),1) -> 0.32083333 | T9: =_xlfn.RANK.EQ(S9,S$3:S$10000,1) -> 63 | U9: =IFERROR(IF(_xlfn.XLOOKUP(B9,'w3'!$B:$B,'w3'!$G:$G)="--",0,_xlfn.XLOOKUP(B9,'w3'!$B:$B,'w3'!$G:$G)),0) -> 594 | V9: =_xlfn.RANK.EQ(U9,U$3:U$10000,0) -> 17 | W9: =IFERROR(_xlfn.XLOOKUP(B9,'w4'!$B:$B,'w4'!$C:$C),0) -> 62.5 | X9: =_xlfn.RANK.EQ(W9,W$3:W$10000,0) -> 5 | Y9: =IFERROR(_xlfn.XLOOKUP(B9,'w4'!$B:$B,'w4'!$F:$F),1) -> 0.36597222 | Z9: =_xlfn.RANK.EQ(Y9,Y$3:Y$10000,1) -> 65 | AA9: =IFERROR(IF(_xlfn.XLOOKUP(B9,'w4'!$B:$B,'w4'!$G:$G)="--",0,_xlfn.XLOOKUP(B9,'w4'!$B:$B,'w4'!$G:$G)),0) -> 1557 | AB9: =_xlfn.RANK.EQ(AA9,AA$3:AA$10000,0) -> 8 | AC9: =IFERROR(_xlfn.XLOOKUP(B9,'w5'!$B:$B,'w5'!$C:$C),0) -> 56.6 | AD9: =_xlfn.RANK.EQ(AC9,AC$3:AC$10000,0) -> 5 | AE9: =IFERROR(_xlfn.XLOOKUP(B9,'w5'!$B:$B,'w5'!$F:$F),1) -> 0.32083333 | AF9: =_xlfn.RANK.EQ(AE9,AE$3:AE$10000,1) -> 49 | AG9: =IFERROR(IF(_xlfn.XLOOKUP(B9,'w5'!$B:$B,'w5'!$G:$G)="--",0,_xlfn.XLOOKUP(B9,'w5'!$B:$B,'w5'!$G:$G)),0) -> 1077 | AH9: =_xlfn.RANK.EQ(AG9,AG$3:AG$10000,0) -> 14 | AI9: =IFERROR(_xlfn.XLOOKUP(B9,'w6'!$B:$B,'w6'!$C:$C),0) -> 45.9 | AJ9: =_xlfn.RANK.EQ(AI9,AI$3:AI$10000,0) -> 7 | AK9: =IFERROR(_xlfn.XLOOKUP(B9,'w6'!$B:$B,'w6'!$F:$F),1) -> 0.29930556 | AL9: =_xlfn.RANK.EQ(AK9,AK$3:AK$10000,1) -> 39 | AM9: =IFERROR(IF(_xlfn.XLOOKUP(B9,'w6'!$B:$B,'w6'!$G:$G)="--",0,_xlfn.XLOOKUP(B9,'w6'!$B:$B,'w6'!$G:$G)),0) -> 804 | AN9: =_xlfn.RANK.EQ(AM9,AM$3:AM$10000,0) -> 10 | AO9: =IFERROR(_xlfn.XLOOKUP(B9,'w7'!$B:$B,'w7'!$C:$C),0) -> 55.8 | AP9: =_xlfn.RANK.EQ(AO9,AO$3:AO$10000,0) -> 8 | AQ9: =IFERROR(_xlfn.XLOOKUP(B9,'w7'!$B:$B,'w7'!$F:$F),1) -> 0.31041667 | AR9: =_xlfn.RANK.EQ(AQ9,AQ$3:AQ$10000,1) -> 46 | AS9: =IFERROR(IF(_xlfn.XLOOKUP(B9,'w7'!$B:$B,'w7'!$G:$G)="--",0,_xlfn.XLOOKUP(B9,'w7'!$B:$B,'w7'!$G:$G)),0) -> 1587 | AT9: =_xlfn.RANK.EQ(AS9,AS$3:AS$10000,0) -> 6 | AU9: =IFERROR(_xlfn.XLOOKUP(B9,'w8'!$B:$B,'w8'!$C:$C),0) -> 51.5 | AV9: =_xlfn.RANK.EQ(AU9,AU$3:AU$10000,0) -> 13 | AW9: =IFERROR(_xlfn.XLOOKUP(B9,'w8'!$B:$B,'w8'!$F:$F),1) -> 0.31736111 | AX9: =_xlfn.RANK.EQ(AW9,AW$3:AW$10000,1) -> 54 | AY9: =IFERROR(IF(_xlfn.XLOOKUP(B9,'w8'!$B:$B,'w8'!$G:$G)="--",0,_xlfn.XLOOKUP(B9,'w8'!$B:$B,'w8'!$G:$G)),0) -> 1125 | AZ9: =_xlfn.RANK.EQ(AY9,AY$3:AY$10000,0) -> 11 | BA9: =IFERROR(_xlfn.XLOOKUP(C9,'w9'!$B:$B,'w9'!$C:$C),0) -> 47.7 | BB9: =_xlfn.RANK.EQ(BA9,BA$3:BA$10000,0) -> 18 | BC9: =IFERROR(_xlfn.XLOOKUP(C9,'w9'!$B:$B,'w9'!$F:$F),1) -> 0.33472222 | BD9: =_xlfn.RANK.EQ(BC9,BC$3:BC$10000,1) -> 58 | BE9: =IFERROR(IF(_xlfn.XLOOKUP(C9,'w9'!$B:$B,'w9'!$G:$G)="--",0,_xlfn.XLOOKUP(C9,'w9'!$B:$B,'w9'!$G:$G)),0) -> 1443 | BF9: =_xlfn.RANK.EQ(BE9,BE$3:BE$10000,0) -> 5 | BG9: =IFERROR(_xlfn.XLOOKUP(B9,'w10'!$B:$B,'w10'!$C:$C),0) -> 70.4 | BH9: =_xlfn.RANK.EQ(BG9,BG$3:BG$10000,0) -> 3 | BI9: =IFERROR(_xlfn.XLOOKUP(B9,'w10'!$B:$B,'w10'!$F:$F),1) -> 0.30694444 | BJ9: =_xlfn.RANK.EQ(BI9,BI$3:BI$10000,1) -> 53 | BK9: =IFERROR(IF(_xlfn.XLOOKUP(B9,'w10'!$B:$B,'w10'!$G:$G)="--",0,_xlfn.XLOOKUP(B9,'w10'!$B:$B,'w10'!$G:$G)),0) -> 2440 | BL9: =_xlfn.RANK.EQ(BK9,BK$3:BK$10000,0) -> 3 | BM9: =IFERROR(_xlfn.XLOOKUP(B9,'w11'!$B:$B,'w11'!$C:$C),0) -> 77.6 | BN9: =_xlfn.RANK.EQ(BM9,BM$3:BM$10000,0) -> 3 | BO9: =IFERROR(_xlfn.XLOOKUP(B9,'w11'!$B:$B,'w11'!$F:$F),1) -> 0.31527778 | BP9: =_xlfn.RANK.EQ(BO9,BO$3:BO$10000,1) -> 55 | BQ9: =IFERROR(IF(_xlfn.XLOOKUP(B9,'w11'!$B:$B,'w11'!$G:$G)="--",0,_xlfn.XLOOKUP(B9,'w11'!$B:$B,'w11'!$G:$G)),0) -> 2174 | BR9: =_xlfn.RANK.EQ(BQ9,BQ$3:BQ$10000,0) -> 3 | BS9: =IFERROR(_xlfn.XLOOKUP(B9,'w12'!$B:$B,'w12'!$C:$C),0) -> 80.7 | BT9: =_xlfn.RANK.EQ(BS9,BS$3:BS$10000,0) -> 4 | BU9: =IFERROR(_xlfn.XLOOKUP(B9,'w12'!$B:$B,'w12'!$F:$F),1) -> 0.31527778 | BV9: =_xlfn.RANK.EQ(BU9,BU$3:BU$10000,1) -> 56 | BW9: =IFERROR(IF(_xlfn.XLOOKUP(B9,'w12'!$B:$B,'w12'!$G:$G)="--",0,_xlfn.XLOOKUP(B9,'w12'!$B:$B,'w12'!$G:$G)),0) -> 2221 | BX9: =_xlfn.RANK.EQ(BW9,BW$3:BW$10000,0) -> 2 | BY9: =IFERROR(_xlfn.XLOOKUP(B9,'w13'!$B:$B,'w13'!$C:$C),0) -> 25.4 | BZ9: =_xlfn.RANK.EQ(BY9,BY$3:BY$10000,0) -> 33 | CA9: =IFERROR(_xlfn.XLOOKUP(B9,'w13'!$B:$B,'w13'!$F:$F),1) -> 0.28541667 | CB9: =_xlfn.RANK.EQ(CA9,CA$3:CA$10000,1) -> 43 | CC9: =IFERROR(IF(_xlfn.XLOOKUP(B9,'w13'!$B:$B,'w13'!$G:$G)="--",0,_xlfn.XLOOKUP(B9,'w13'!$B:$B,'w13'!$G:$G)),0) -> 135 | CD9: =_xlfn.RANK.EQ(CC9,CC$3:CC$10000,0) -> 43 | CE9: =IFERROR(_xlfn.XLOOKUP(B9,'w14'!$B:$B,'w14'!$C:$C),0) -> 65.8 | CF9: =_xlfn.RANK.EQ(CE9,CE$3:CE$10000,0) -> 5 | CG9: =IFERROR(_xlfn.XLOOKUP(B9,'w14'!$B:$B,'w14'!$F:$F),1) -> 0.32708333 | CH9: =_xlfn.RANK.EQ(CG9,CG$3:CG$10000,1) -> 50 | CI9: =IFERROR(IF(_xlfn.XLOOKUP(B9,'w14'!$B:$B,'w14'!$G:$G)="--",0,_xlfn.XLOOKUP(B9,'w14'!$B:$B,'w14'!$G:$G)),0) -> 1612 | CJ9: =_xlfn.RANK.EQ(CI9,CI$3:CI$10000,0) -> 7 | CK9: =_xlfn.RANK.EQ(D9,D$3:D$10000,1) -> 7 | CL9: Marina Marques | CM9: =SUM(E9,K9,Q9,W9,AC9,AI9,AO9,AU9,BA9,BG9,BM9,BS9,BY9,CE9) -> 747 | CN9: =_xlfn.RANK.EQ(CM9,CM$3:CM$10000) -> 7 | CO9: =IFERROR(SUM(PRODUCT(E9,G9),PRODUCT(K9,M9),PRODUCT(Q9,S9),PRODUCT(W9,Y9),PRODUCT(AC9,AE9),PRODUCT(AI9,AK9),PRODUCT(AO9,AQ9),PRODUCT(AU9,AW9),PRODUCT(BA9,BC9),PRODUCT(BG9,BI9),PRODUCT(BM9,BO9),PRODUCT(BS9,BU9),PRODUCT(BY9,CA9),PRODUCT(CE9,CG9))/CM9,1) -> 0.3190063 | CP9: =_xlfn.RANK.EQ(CO9,CO$3:CO$10000,1) -> 70 | CQ9: =SUM(I9,O9,U9,AA9,AG9,AM9,AS9,AY9,BE9,BK9,BQ9,BW9,CC9,CI9) -> 18909 | CR9: =_xlfn.RANK.EQ(CQ9,CQ$3:CQ$10000) -> 7 | CS9: =_xlfn.RANK.EQ(CT9,CT$3:CT$10000,1) -> 8 | CT9: =CV9*$CN$1+CX9*$CP$1+CZ9*$CR$1 -> 34.525 | CU9: =_xlfn.STDEV.S(F9,L9,R9,X9,AD9,AJ9,AP9,AV9,BB9,BH9,BN9,BT9,BZ9,CF9) -> 10.672961 | CV9: =_xlfn.RANK.EQ(CU9,CU$3:CU$10000,1) -> 34 | CW9: =_xlfn.STDEV.S(H9,N9,T9,Z9,AF9,AL9,AR9,AX9,BD9,BJ9,BP9,BV9,CB9,CH9) -> 12.4141 | CX9: =_xlfn.RANK.EQ(CW9,CW$3:CW$10000,1) -> 38 | CY9: =_xlfn.STDEV.S(J9,P9,V9,AB9,AH9,AN9,AT9,AZ9,BF9,BL9,BR9,BX9,CD9,CJ9) -> 14.308992 | CZ9: =_xlfn.RANK.EQ(CY9,CY$3:CY$10000,1) -> 51 | DA9: =SUM(COUNTIF(E9,">0"),COUNTIF(K9,">0"),COUNTIF(Q9,">0"),COUNTIF(W9,">0"),COUNTIF(AC9,">0"),COUNTIF(AI9,">0"),COUNTIF(AO9,">0"),COUNTIF(AU9,">0"),COUNTIF(BA9,">0"),COUNTIF(BG9,">0"),COUNTIF(BM9,">0"),COUNTIF(BS9,">0"),COUNTIF(BY9,">0"),COUNTIF(CE9,">0")) -> 14
B10: Vitor Pires Vitor Pires | C10: Vitor Pires | D10: =CN10*$CN$1+CP10*$CP$1+CR10*$CR$1 -> 10.1 | E10: =IFERROR(_xlfn.XLOOKUP(B10,'w1'!$B:$B,'w1'!$C:$C),0) -> 22.6 | F10: =_xlfn.RANK.EQ(E10,E$3:E$10000,0) -> 39 | G10: =IFERROR(_xlfn.XLOOKUP(B10,'w1'!$B:$B,'w1'!$F:$F),1) -> 0.26458333 | H10: =_xlfn.RANK.EQ(G10,G$3:G$10000,1) -> 32 | I10: =IFERROR(IF(_xlfn.XLOOKUP(B10,'w1'!$B:$B,'w1'!$G:$G)="--",0,_xlfn.XLOOKUP(B10,'w1'!$B:$B,'w1'!$G:$G)),0) -> 69 | J10: =_xlfn.RANK.EQ(I10,I$3:I$10000,0) -> 60 | K10: =IFERROR(_xlfn.XLOOKUP(B10,'w2'!$B:$B,'w2'!$C:$C),0) -> 45.2 | L10: =_xlfn.RANK.EQ(K10,K$3:K$10000,0) -> 12 | M10: =IFERROR(_xlfn.XLOOKUP(B10,'w2'!$B:$B,'w2'!$F:$F),1) -> 0.26805556 | N10: =_xlfn.RANK.EQ(M10,M$3:M$10000,1) -> 26 | O10: =IFERROR(IF(_xlfn.XLOOKUP(B10,'w2'!$B:$B,'w2'!$G:$G)="--",0,_xlfn.XLOOKUP(B10,'w2'!$B:$B,'w2'!$G:$G)),0) -> 221 | P10: =_xlfn.RANK.EQ(O10,O$3:O$10000,0) -> 35 | Q10: =IFERROR(_xlfn.XLOOKUP(B10,'w3'!$B:$B,'w3'!$C:$C),0) -> 46 | R10: =_xlfn.RANK.EQ(Q10,Q$3:Q$10000,0) -> 14 | S10: =IFERROR(_xlfn.XLOOKUP(B10,'w3'!$B:$B,'w3'!$F:$F),1) -> 0.25486111 | T10: =_xlfn.RANK.EQ(S10,S$3:S$10000,1) -> 26 | U10: =IFERROR(IF(_xlfn.XLOOKUP(B10,'w3'!$B:$B,'w3'!$G:$G)="--",0,_xlfn.XLOOKUP(B10,'w3'!$B:$B,'w3'!$G:$G)),0) -> 149 | V10: =_xlfn.RANK.EQ(U10,U$3:U$10000,0) -> 42 | W10: =IFERROR(_xlfn.XLOOKUP(B10,'w4'!$B:$B,'w4'!$C:$C),0) -> 40.7 | X10: =_xlfn.RANK.EQ(W10,W$3:W$10000,0) -> 14 | Y10: =IFERROR(_xlfn.XLOOKUP(B10,'w4'!$B:$B,'w4'!$F:$F),1) -> 0.24513889 | Z10: =_xlfn.RANK.EQ(Y10,Y$3:Y$10000,1) -> 19 | AA10: =IFERROR(IF(_xlfn.XLOOKUP(B10,'w4'!$B:$B,'w4'!$G:$G)="--",0,_xlfn.XLOOKUP(B10,'w4'!$B:$B,'w4'!$G:$G)),0) -> 226 | AB10: =_xlfn.RANK.EQ(AA10,AA$3:AA$10000,0) -> 34 | AC10: =IFERROR(_xlfn.XLOOKUP(B10,'w5'!$B:$B,'w5'!$C:$C),0) -> 45.5 | AD10: =_xlfn.RANK.EQ(AC10,AC$3:AC$10000,0) -> 12 | AE10: =IFERROR(_xlfn.XLOOKUP(B10,'w5'!$B:$B,'w5'!$F:$F),1) -> 0.25069444 | AF10: =_xlfn.RANK.EQ(AE10,AE$3:AE$10000,1) -> 19 | AG10: =IFERROR(IF(_xlfn.XLOOKUP(B10,'w5'!$B:$B,'w5'!$G:$G)="--",0,_xlfn.XLOOKUP(B10,'w5'!$B:$B,'w5'!$G:$G)),0) -> 256 | AH10: =_xlfn.RANK.EQ(AG10,AG$3:AG$10000,0) -> 39 | AI10: =IFERROR(_xlfn.XLOOKUP(B10,'w6'!$B:$B,'w6'!$C:$C),0) -> 38.1 | AJ10: =_xlfn.RANK.EQ(AI10,AI$3:AI$10000,0) -> 12 | AK10: =IFERROR(_xlfn.XLOOKUP(B10,'w6'!$B:$B,'w6'!$F:$F),1) -> 0.23819444 | AL10: =_xlfn.RANK.EQ(AK10,AK$3:AK$10000,1) -> 8 | AM10: =IFERROR(IF(_xlfn.XLOOKUP(B10,'w6'!$B:$B,'w6'!$G:$G)="--",0,_xlfn.XLOOKUP(B10,'w6'!$B:$B,'w6'!$G:$G)),0) -> 156 | AN10: =_xlfn.RANK.EQ(AM10,AM$3:AM$10000,0) -> 40 | AO10: =IFERROR(_xlfn.XLOOKUP(B10,'w7'!$B:$B,'w7'!$C:$C),0) -> 56.3 | AP10: =_xlfn.RANK.EQ(AO10,AO$3:AO$10000,0) -> 7 | AQ10: =IFERROR(_xlfn.XLOOKUP(B10,'w7'!$B:$B,'w7'!$F:$F),1) -> 0.23055556 | AR10: =_xlfn.RANK.EQ(AQ10,AQ$3:AQ$10000,1) -> 10 | AS10: =IFERROR(IF(_xlfn.XLOOKUP(B10,'w7'!$B:$B,'w7'!$G:$G)="--",0,_xlfn.XLOOKUP(B10,'w7'!$B:$B,'w7'!$G:$G)),0) -> 187 | AT10: =_xlfn.RANK.EQ(AS10,AS$3:AS$10000,0) -> 37 | AU10: =IFERROR(_xlfn.XLOOKUP(B10,'w8'!$B:$B,'w8'!$C:$C),0) -> 54.6 | AV10: =_xlfn.RANK.EQ(AU10,AU$3:AU$10000,0) -> 8 | AW10: =IFERROR(_xlfn.XLOOKUP(B10,'w8'!$B:$B,'w8'!$F:$F),1) -> 0.22569444 | AX10: =_xlfn.RANK.EQ(AW10,AW$3:AW$10000,1) -> 5 | AY10: =IFERROR(IF(_xlfn.XLOOKUP(B10,'w8'!$B:$B,'w8'!$G:$G)="--",0,_xlfn.XLOOKUP(B10,'w8'!$B:$B,'w8'!$G:$G)),0) -> 117 | AZ10: =_xlfn.RANK.EQ(AY10,AY$3:AY$10000,0) -> 51 | BA10: =IFERROR(_xlfn.XLOOKUP(C10,'w9'!$B:$B,'w9'!$C:$C),0) -> 61.4 | BB10: =_xlfn.RANK.EQ(BA10,BA$3:BA$10000,0) -> 7 | BC10: =IFERROR(_xlfn.XLOOKUP(C10,'w9'!$B:$B,'w9'!$F:$F),1) -> 0.23194444 | BD10: =_xlfn.RANK.EQ(BC10,BC$3:BC$10000,1) -> 8 | BE10: =IFERROR(IF(_xlfn.XLOOKUP(C10,'w9'!$B:$B,'w9'!$G:$G)="--",0,_xlfn.XLOOKUP(C10,'w9'!$B:$B,'w9'!$G:$G)),0) -> 110 | BF10: =_xlfn.RANK.EQ(BE10,BE$3:BE$10000,0) -> 60 | BG10: =IFERROR(_xlfn.XLOOKUP(B10,'w10'!$B:$B,'w10'!$C:$C),0) -> 48.2 | BH10: =_xlfn.RANK.EQ(BG10,BG$3:BG$10000,0) -> 13 | BI10: =IFERROR(_xlfn.XLOOKUP(B10,'w10'!$B:$B,'w10'!$F:$F),1) -> 0.23402778 | BJ10: =_xlfn.RANK.EQ(BI10,BI$3:BI$10000,1) -> 12 | BK10: =IFERROR(IF(_xlfn.XLOOKUP(B10,'w10'!$B:$B,'w10'!$G:$G)="--",0,_xlfn.XLOOKUP(B10,'w10'!$B:$B,'w10'!$G:$G)),0) -> 124 | BL10: =_xlfn.RANK.EQ(BK10,BK$3:BK$10000,0) -> 54 | BM10: =IFERROR(_xlfn.XLOOKUP(B10,'w11'!$B:$B,'w11'!$C:$C),0) -> 43.9 | BN10: =_xlfn.RANK.EQ(BM10,BM$3:BM$10000,0) -> 13 | BO10: =IFERROR(_xlfn.XLOOKUP(B10,'w11'!$B:$B,'w11'!$F:$F),1) -> 0.23541667 | BP10: =_xlfn.RANK.EQ(BO10,BO$3:BO$10000,1) -> 15 | BQ10: =IFERROR(IF(_xlfn.XLOOKUP(B10,'w11'!$B:$B,'w11'!$G:$G)="--",0,_xlfn.XLOOKUP(B10,'w11'!$B:$B,'w11'!$G:$G)),0) -> 157 | BR10: =_xlfn.RANK.EQ(BQ10,BQ$3:BQ$10000,0) -> 45 | BS10: =IFERROR(_xlfn.XLOOKUP(B10,'w12'!$B:$B,'w12'!$C:$C),0) -> 46.3 | BT10: =_xlfn.RANK.EQ(BS10,BS$3:BS$10000,0) -> 9 | BU10: =IFERROR(_xlfn.XLOOKUP(B10,'w12'!$B:$B,'w12'!$F:$F),1) -> 0.22777778 | BV10: =_xlfn.RANK.EQ(BU10,BU$3:BU$10000,1) -> 7 | BW10: =IFERROR(IF(_xlfn.XLOOKUP(B10,'w12'!$B:$B,'w12'!$G:$G)="--",0,_xlfn.XLOOKUP(B10,'w12'!$B:$B,'w12'!$G:$G)),0) -> 123 | BX10: =_xlfn.RANK.EQ(BW10,BW$3:BW$10000,0) -> 52 | BY10: =IFERROR(_xlfn.XLOOKUP(B10,'w13'!$B:$B,'w13'!$C:$C),0) -> 65.2 | BZ10: =_xlfn.RANK.EQ(BY10,BY$3:BY$10000,0) -> 6 | CA10: =IFERROR(_xlfn.XLOOKUP(B10,'w13'!$B:$B,'w13'!$F:$F),1) -> 0.22430556 | CB10: =_xlfn.RANK.EQ(CA10,CA$3:CA$10000,1) -> 8 | CC10: =IFERROR(IF(_xlfn.XLOOKUP(B10,'w13'!$B:$B,'w13'!$G:$G)="--",0,_xlfn.XLOOKUP(B10,'w13'!$B:$B,'w13'!$G:$G)),0) -> 93 | CD10: =_xlfn.RANK.EQ(CC10,CC$3:CC$10000,0) -> 53 | CE10: =IFERROR(_xlfn.XLOOKUP(B10,'w14'!$B:$B,'w14'!$C:$C),0) -> 57.6 | CF10: =_xlfn.RANK.EQ(CE10,CE$3:CE$10000,0) -> 9 | CG10: =IFERROR(_xlfn.XLOOKUP(B10,'w14'!$B:$B,'w14'!$F:$F),1) -> 0.22013889 | CH10: =_xlfn.RANK.EQ(CG10,CG$3:CG$10000,1) -> 4 | CI10: =IFERROR(IF(_xlfn.XLOOKUP(B10,'w14'!$B:$B,'w14'!$G:$G)="--",0,_xlfn.XLOOKUP(B10,'w14'!$B:$B,'w14'!$G:$G)),0) -> 52 | CJ10: =_xlfn.RANK.EQ(CI10,CI$3:CI$10000,0) -> 58 | CK10: =_xlfn.RANK.EQ(D10,D$3:D$10000,1) -> 8 | CL10: Vítor Pires | CM10: =SUM(E10,K10,Q10,W10,AC10,AI10,AO10,AU10,BA10,BG10,BM10,BS10,BY10,CE10) -> 671.6 | CN10: =_xlfn.RANK.EQ(CM10,CM$3:CM$10000) -> 9 | CO10: =IFERROR(SUM(PRODUCT(E10,G10),PRODUCT(K10,M10),PRODUCT(Q10,S10),PRODUCT(W10,Y10),PRODUCT(AC10,AE10),PRODUCT(AI10,AK10),PRODUCT(AO10,AQ10),PRODUCT(AU10,AW10),PRODUCT(BA10,BC10),PRODUCT(BG10,BI10),PRODUCT(BM10,BO10),PRODUCT(BS10,BU10),PRODUCT(BY10,CA10),PRODUCT(CE10,CG10))/CM10,1) -> 0.2371778 | CP10: =_xlfn.RANK.EQ(CO10,CO$3:CO$10000,1) -> 9 | CQ10: =SUM(I10,O10,U10,AA10,AG10,AM10,AS10,AY10,BE10,BK10,BQ10,BW10,CC10,CI10) -> 2040 | CR10: =_xlfn.RANK.EQ(CQ10,CQ$3:CQ$10000) -> 53 | CS10: =_xlfn.RANK.EQ(CT10,CT$3:CT$10000,1) -> 5 | CT10: =CV10*$CN$1+CX10*$CP$1+CZ10*$CR$1 -> 25.75 | CU10: =_xlfn.STDEV.S(F10,L10,R10,X10,AD10,AJ10,AP10,AV10,BB10,BH10,BN10,BT10,BZ10,CF10) -> 8.1121941 | CV10: =_xlfn.RANK.EQ(CU10,CU$3:CU$10000,1) -> 26 | CW10: =_xlfn.STDEV.S(H10,N10,T10,Z10,AF10,AL10,AR10,AX10,BD10,BJ10,BP10,BV10,CB10,CH10) -> 8.8594024 | CX10: =_xlfn.RANK.EQ(CW10,CW$3:CW$10000,1) -> 19 | CY10: =_xlfn.STDEV.S(J10,P10,V10,AB10,AH10,AN10,AT10,AZ10,BF10,BL10,BR10,BX10,CD10,CJ10) -> 9.3632435 | CZ10: =_xlfn.RANK.EQ(CY10,CY$3:CY$10000,1) -> 23 | DA10: =SUM(COUNTIF(E10,">0"),COUNTIF(K10,">0"),COUNTIF(Q10,">0"),COUNTIF(W10,">0"),COUNTIF(AC10,">0"),COUNTIF(AI10,">0"),COUNTIF(AO10,">0"),COUNTIF(AU10,">0"),COUNTIF(BA10,">0"),COUNTIF(BG10,">0"),COUNTIF(BM10,">0"),COUNTIF(BS10,">0"),COUNTIF(BY10,">0"),COUNTIF(CE10,">0")) -> 14
